Workbook

Sheet 【表示用】各メンバーCH
B2: ◆各メンバーCH（成立＋確度A）
D3: 9月 | E3: 10月 | F3: 11月 | G3: 12月 | H3: 1月 | I3: 2月 | J3: 3月 | K3: 4月 | L3: 5月 | M3: 6月 | N3: 7月 | O3: 8月
B4: 波多野 | C4: ①目標 | D4: 0.3 | E4: 0.3 | F4: 0.3 | G4: 0.3 | H4: 0.3 | I4: 0.3 | J4: 0.3 | K4: 0.3 | L4: 0.3 | M4: 0.3 | N4: 0.3 | O4: 0.3
C5: ②見積 | D5: =SUMIFS('【入力用③】案件ごとCH（D案件以上）'!O$5:O$1048576,'【入力用③】案件ごとCH（D案件以上）'!$N$5:$N$1048576,【表示用】各メンバーCH!$B4,'【入力用③】案件ごとCH（D案件以上）'!$H$5:$H$1048576,"成立")+SUMIFS('【入力用③】案件ごとCH（D案件以上）'!O$5:O$1048576,'【入力用③】案件ごとCH（D案件以上）'!$N$5:$N$1048576,【表示用】各メンバーCH!$B4,'【入力用③】案件ごとCH（D案件以上）'!$H$5:$H$1048576,"A") -> 0.28 | E5: =SUMIFS('【入力用③】案件ごとCH（D案件以上）'!P$5:P$1048576,'【入力用③】案件ごとCH（D案件以上）'!$N$5:$N$1048576,【表示用】各メンバーCH!$B4,'【入力用③】案件ごとCH（D案件以上）'!$H$5:$H$1048576,"成立")+SUMIFS('【入力用③】案件ごとCH（D案件以上）'!P$5:P$1048576,'【入力用③】案件ごとCH（D案件以上）'!$N$5:$N$1048576,【表示用】各メンバーCH!$B4,'【入力用③】案件ごとCH（D案件以上）'!$H$5:$H$1048576,"A") -> 0.33 | F5: =SUMIFS('【入力用③】案件ごとCH（D案件以上）'!Q$5:Q$1048576,'【入力用③】案件ごとCH（D案件以上）'!$N$5:$N$1048576,【表示用】各メンバーCH!$B4,'【入力用③】案件ごとCH（D案件以上）'!$H$5:$H$1048576,"成立")+SUMIFS('【入力用③】案件ごとCH（D案件以上）'!Q$5:Q$1048576,'【入力用③】案件ごとCH（D案件以上）'!$N$5:$N$1048576,【表示用】各メンバーCH!$B4,'【入力用③】案件ごとCH（D案件以上）'!$H$5:$H$1048576,"A") -> 0.31 | G5: =SUMIFS('【入力用③】案件ごとCH（D案件以上）'!R$5:R$1048576,'【入力用③】案件ごとCH（D案件以上）'!$N$5:$N$1048576,【表示用】各メンバーCH!$B4,'【入力用③】案件ごとCH（D案件以上）'!$H$5:$H$1048576,"成立")+SUMIFS('【入力用③】案件ごとCH（D案件以上）'!R$5:R$1048576,'【入力用③】案件ごとCH（D案件以上）'!$N$5:$N$1048576,【表示用】各メンバーCH!$B4,'【入力用③】案件ごとCH（D案件以上）'!$H$5:$H$1048576,"A") -> 0.31 | H5: =SUMIFS('【入力用③】案件ごとCH（D案件以上）'!S$5:S$1048576,'【入力用③】案件ごとCH（D案件以上）'!$N$5:$N$1048576,【表示用】各メンバーCH!$B4,'【入力用③】案件ごとCH（D案件以上）'!$H$5:$H$1048576,"成立")+SUMIFS('【入力用③】案件ごとCH（D案件以上）'!S$5:S$1048576,'【入力用③】案件ごとCH（D案件以上）'!$N$5:$N$1048576,【表示用】各メンバーCH!$B4,'【入力用③】案件ごとCH（D案件以上）'!$H$5:$H$1048576,"A") -> 0.19 | I5: =SUMIFS('【入力用③】案件ごとCH（D案件以上）'!T$5:T$1048576,'【入力用③】案件ごとCH（D案件以上）'!$N$5:$N$1048576,【表示用】各メンバーCH!$B4,'【入力用③】案件ごとCH（D案件以上）'!$H$5:$H$1048576,"成立")+SUMIFS('【入力用③】案件ごとCH（D案件以上）'!T$5:T$1048576,'【入力用③】案件ごとCH（D案件以上）'!$N$5:$N$1048576,【表示用】各メンバーCH!$B4,'【入力用③】案件ごとCH（D案件以上）'!$H$5:$H$1048576,"A") -> 0.2 | J5: =SUMIFS('【入力用③】案件ごとCH（D案件以上）'!U$5:U$1048576,'【入力用③】案件ごとCH（D案件以上）'!$N$5:$N$1048576,【表示用】各メンバーCH!$B4,'【入力用③】案件ごとCH（D案件以上）'!$H$5:$H$1048576,"成立")+SUMIFS('【入力用③】案件ごとCH（D案件以上）'!U$5:U$1048576,'【入力用③】案件ごとCH（D案件以上）'!$N$5:$N$1048576,【表示用】各メンバーCH!$B4,'【入力用③】案件ごとCH（D案件以上）'!$H$5:$H$1048576,"A") -> 0.2 | K5: =SUMIFS('【入力用③】案件ごとCH（D案件以上）'!V$5:V$1048576,'【入力用③】案件ごとCH（D案件以上）'!$N$5:$N$1048576,【表示用】各メンバーCH!$B4,'【入力用③】案件ごとCH（D案件以上）'!$H$5:$H$1048576,"成立")+SUMIFS('【入力用③】案件ごとCH（D案件以上）'!V$5:V$1048576,'【入力用③】案件ごとCH（D案件以上）'!$N$5:$N$1048576,【表示用】各メンバーCH!$B4,'【入力用③】案件ごとCH（D案件以上）'!$H$5:$H$1048576,"A") -> 0.2 | ... O5: =SUMIFS('【入力用③】案件ごとCH（D案件以上）'!Z$5:Z$1048576,'【入力用③】案件ごとCH（D案件以上）'!$N$5:$N$1048576,【表示用】各メンバーCH!$B4,'【入力用③】案件ごとCH（D案件以上）'!$H$5:$H$1048576,"成立")+SUMIFS('【入力用③】案件ごとCH（D案件以上）'!Z$5:Z$1048576,'【入力用③】案件ごとCH（D案件以上）'!$N$5:$N$1048576,【表示用】各メンバーCH!$B4,'【入力用③】案件ごとCH（D案件以上）'!$H$5:$H$1048576,"A") -> 0
C6: ③GAP（②-①） | D6: =D5-D4 -> -0.02 | E6: =E5-E4 -> 0.03 | F6: =F5-F4 -> 0.01 | G6: =G5-G4 -> 0.01 | H6: =H5-H4 -> -0.11 | I6: =I5-I4 -> -0.1 | J6: =J5-J4 -> -0.1 | K6: =K5-K4 -> -0.1 | ... O6: =O5-O4 -> -0.3
B7: 小川 | C7: ①目標 | D7: 0.5 | E7: 0.5 | F7: 0.5 | G7: 0.5 | H7: 0.5 | I7: 0.5 | J7: 0.5 | K7: 0.5 | L7: 0.5 | M7: 0.5 | N7: 0.5 | O7: 0.5
C8: ②見積 | D8: =SUMIFS('【入力用③】案件ごとCH（D案件以上）'!O$5:O$1048576,'【入力用③】案件ごとCH（D案件以上）'!$N$5:$N$1048576,【表示用】各メンバーCH!$B7,'【入力用③】案件ごとCH（D案件以上）'!$H$5:$H$1048576,"成立")+SUMIFS('【入力用③】案件ごとCH（D案件以上）'!O$5:O$1048576,'【入力用③】案件ごとCH（D案件以上）'!$N$5:$N$1048576,【表示用】各メンバーCH!$B7,'【入力用③】案件ごとCH（D案件以上）'!$H$5:$H$1048576,"A") -> 0.209 | E8: =SUMIFS('【入力用③】案件ごとCH（D案件以上）'!P$5:P$1048576,'【入力用③】案件ごとCH（D案件以上）'!$N$5:$N$1048576,【表示用】各メンバーCH!$B7,'【入力用③】案件ごとCH（D案件以上）'!$H$5:$H$1048576,"成立")+SUMIFS('【入力用③】案件ごとCH（D案件以上）'!P$5:P$1048576,'【入力用③】案件ごとCH（D案件以上）'!$N$5:$N$1048576,【表示用】各メンバーCH!$B7,'【入力用③】案件ごとCH（D案件以上）'!$H$5:$H$1048576,"A") -> 0.14 | F8: =SUMIFS('【入力用③】案件ごとCH（D案件以上）'!Q$5:Q$1048576,'【入力用③】案件ごとCH（D案件以上）'!$N$5:$N$1048576,【表示用】各メンバーCH!$B7,'【入力用③】案件ごとCH（D案件以上）'!$H$5:$H$1048576,"成立")+SUMIFS('【入力用③】案件ごとCH（D案件以上）'!Q$5:Q$1048576,'【入力用③】案件ごとCH（D案件以上）'!$N$5:$N$1048576,【表示用】各メンバーCH!$B7,'【入力用③】案件ごとCH（D案件以上）'!$H$5:$H$1048576,"A") -> 0.14 | G8: =SUMIFS('【入力用③】案件ごとCH（D案件以上）'!R$5:R$1048576,'【入力用③】案件ごとCH（D案件以上）'!$N$5:$N$1048576,【表示用】各メンバーCH!$B7,'【入力用③】案件ごとCH（D案件以上）'!$H$5:$H$1048576,"成立")+SUMIFS('【入力用③】案件ごとCH（D案件以上）'!R$5:R$1048576,'【入力用③】案件ごとCH（D案件以上）'!$N$5:$N$1048576,【表示用】各メンバーCH!$B7,'【入力用③】案件ごとCH（D案件以上）'!$H$5:$H$1048576,"A") -> 0.14 | H8: =SUMIFS('【入力用③】案件ごとCH（D案件以上）'!S$5:S$1048576,'【入力用③】案件ごとCH（D案件以上）'!$N$5:$N$1048576,【表示用】各メンバーCH!$B7,'【入力用③】案件ごとCH（D案件以上）'!$H$5:$H$1048576,"成立")+SUMIFS('【入力用③】案件ごとCH（D案件以上）'!S$5:S$1048576,'【入力用③】案件ごとCH（D案件以上）'!$N$5:$N$1048576,【表示用】各メンバーCH!$B7,'【入力用③】案件ごとCH（D案件以上）'!$H$5:$H$1048576,"A") -> 0.13 | I8: =SUMIFS('【入力用③】案件ごとCH（D案件以上）'!T$5:T$1048576,'【入力用③】案件ごとCH（D案件以上）'!$N$5:$N$1048576,【表示用】各メンバーCH!$B7,'【入力用③】案件ごとCH（D案件以上）'!$H$5:$H$1048576,"成立")+SUMIFS('【入力用③】案件ごとCH（D案件以上）'!T$5:T$1048576,'【入力用③】案件ごとCH（D案件以上）'!$N$5:$N$1048576,【表示用】各メンバーCH!$B7,'【入力用③】案件ごとCH（D案件以上）'!$H$5:$H$1048576,"A") -> 0.21 | J8: =SUMIFS('【入力用③】案件ごとCH（D案件以上）'!U$5:U$1048576,'【入力用③】案件ごとCH（D案件以上）'!$N$5:$N$1048576,【表示用】各メンバーCH!$B7,'【入力用③】案件ごとCH（D案件以上）'!$H$5:$H$1048576,"成立")+SUMIFS('【入力用③】案件ごとCH（D案件以上）'!U$5:U$1048576,'【入力用③】案件ごとCH（D案件以上）'!$N$5:$N$1048576,【表示用】各メンバーCH!$B7,'【入力用③】案件ごとCH（D案件以上）'!$H$5:$H$1048576,"A") -> 0.08 | K8: =SUMIFS('【入力用③】案件ごとCH（D案件以上）'!V$5:V$1048576,'【入力用③】案件ごとCH（D案件以上）'!$N$5:$N$1048576,【表示用】各メンバーCH!$B7,'【入力用③】案件ごとCH（D案件以上）'!$H$5:$H$1048576,"成立")+SUMIFS('【入力用③】案件ごとCH（D案件以上）'!V$5:V$1048576,'【入力用③】案件ごとCH（D案件以上）'!$N$5:$N$1048576,【表示用】各メンバーCH!$B7,'【入力用③】案件ごとCH（D案件以上）'!$H$5:$H$1048576,"A") -> 0 | ... O8: =SUMIFS('【入力用③】案件ごとCH（D案件以上）'!Z$5:Z$1048576,'【入力用③】案件ごとCH（D案件以上）'!$N$5:$N$1048576,【表示用】各メンバーCH!$B7,'【入力用③】案件ごとCH（D案件以上）'!$H$5:$H$1048576,"成立")+SUMIFS('【入力用③】案件ごとCH（D案件以上）'!Z$5:Z$1048576,'【入力用③】案件ごとCH（D案件以上）'!$N$5:$N$1048576,【表示用】各メンバーCH!$B7,'【入力用③】案件ごとCH（D案件以上）'!$H$5:$H$1048576,"A") -> 0
C9: ③GAP（②-①） | D9: =D8-D7 -> -0.291 | E9: =E8-E7 -> -0.36 | F9: =F8-F7 -> -0.36 | G9: =G8-G7 -> -0.36 | H9: =H8-H7 -> -0.37 | I9: =I8-I7 -> -0.29 | J9: =J8-J7 -> -0.42 | K9: =K8-K7 -> -0.5 | ... O9: =O8-O7 -> -0.5
B10: 啓亮 | C10: ①目標 | D10: 0.8 | E10: 0.8 | F10: 0.8 | G10: 0.8 | H10: 0.8 | I10: 0.8 | J10: 0.8 | K10: 0.8 | L10: 0.8 | M10: 0.8 | N10: 0.8 | O10: 0.8
C11: ②見積 | D11: =SUMIFS('【入力用③】案件ごとCH（D案件以上）'!O$5:O$1048576,'【入力用③】案件ごとCH（D案件以上）'!$N$5:$N$1048576,【表示用】各メンバーCH!$B10,'【入力用③】案件ごとCH（D案件以上）'!$H$5:$H$1048576,"成立")+SUMIFS('【入力用③】案件ごとCH（D案件以上）'!O$5:O$1048576,'【入力用③】案件ごとCH（D案件以上）'!$N$5:$N$1048576,【表示用】各メンバーCH!$B10,'【入力用③】案件ごとCH（D案件以上）'!$H$5:$H$1048576,"A") -> 0.5246 | E11: =SUMIFS('【入力用③】案件ごとCH（D案件以上）'!P$5:P$1048576,'【入力用③】案件ごとCH（D案件以上）'!$N$5:$N$1048576,【表示用】各メンバーCH!$B10,'【入力用③】案件ごとCH（D案件以上）'!$H$5:$H$1048576,"成立")+SUMIFS('【入力用③】案件ごとCH（D案件以上）'!P$5:P$1048576,'【入力用③】案件ごとCH（D案件以上）'!$N$5:$N$1048576,【表示用】各メンバーCH!$B10,'【入力用③】案件ごとCH（D案件以上）'!$H$5:$H$1048576,"A") -> 0.444 | F11: =SUMIFS('【入力用③】案件ごとCH（D案件以上）'!Q$5:Q$1048576,'【入力用③】案件ごとCH（D案件以上）'!$N$5:$N$1048576,【表示用】各メンバーCH!$B10,'【入力用③】案件ごとCH（D案件以上）'!$H$5:$H$1048576,"成立")+SUMIFS('【入力用③】案件ごとCH（D案件以上）'!Q$5:Q$1048576,'【入力用③】案件ごとCH（D案件以上）'!$N$5:$N$1048576,【表示用】各メンバーCH!$B10,'【入力用③】案件ごとCH（D案件以上）'!$H$5:$H$1048576,"A") -> 0.784 | G11: =SUMIFS('【入力用③】案件ごとCH（D案件以上）'!R$5:R$1048576,'【入力用③】案件ごとCH（D案件以上）'!$N$5:$N$1048576,【表示用】各メンバーCH!$B10,'【入力用③】案件ごとCH（D案件以上）'!$H$5:$H$1048576,"成立")+SUMIFS('【入力用③】案件ごとCH（D案件以上）'!R$5:R$1048576,'【入力用③】案件ごとCH（D案件以上）'!$N$5:$N$1048576,【表示用】各メンバーCH!$B10,'【入力用③】案件ごとCH（D案件以上）'!$H$5:$H$1048576,"A") -> 0.51 | H11: =SUMIFS('【入力用③】案件ごとCH（D案件以上）'!S$5:S$1048576,'【入力用③】案件ごとCH（D案件以上）'!$N$5:$N$1048576,【表示用】各メンバーCH!$B10,'【入力用③】案件ごとCH（D案件以上）'!$H$5:$H$1048576,"成立")+SUMIFS('【入力用③】案件ごとCH（D案件以上）'!S$5:S$1048576,'【入力用③】案件ごとCH（D案件以上）'!$N$5:$N$1048576,【表示用】各メンバーCH!$B10,'【入力用③】案件ごとCH（D案件以上）'!$H$5:$H$1048576,"A") -> 1.61 | I11: =SUMIFS('【入力用③】案件ごとCH（D案件以上）'!T$5:T$1048576,'【入力用③】案件ごとCH（D案件以上）'!$N$5:$N$1048576,【表示用】各メンバーCH!$B10,'【入力用③】案件ごとCH（D案件以上）'!$H$5:$H$1048576,"成立")+SUMIFS('【入力用③】案件ごとCH（D案件以上）'!T$5:T$1048576,'【入力用③】案件ごとCH（D案件以上）'!$N$5:$N$1048576,【表示用】各メンバーCH!$B10,'【入力用③】案件ごとCH（D案件以上）'!$H$5:$H$1048576,"A") -> 1.685 | J11: =SUMIFS('【入力用③】案件ごとCH（D案件以上）'!U$5:U$1048576,'【入力用③】案件ごとCH（D案件以上）'!$N$5:$N$1048576,【表示用】各メンバーCH!$B10,'【入力用③】案件ごとCH（D案件以上）'!$H$5:$H$1048576,"成立")+SUMIFS('【入力用③】案件ごとCH（D案件以上）'!U$5:U$1048576,'【入力用③】案件ごとCH（D案件以上）'!$N$5:$N$1048576,【表示用】各メンバーCH!$B10,'【入力用③】案件ごとCH（D案件以上）'!$H$5:$H$1048576,"A") -> 1.49 | K11: =SUMIFS('【入力用③】案件ごとCH（D案件以上）'!V$5:V$1048576,'【入力用③】案件ごとCH（D案件以上）'!$N$5:$N$1048576,【表示用】各メンバーCH!$B10,'【入力用③】案件ごとCH（D案件以上）'!$H$5:$H$1048576,"成立")+SUMIFS('【入力用③】案件ごとCH（D案件以上）'!V$5:V$1048576,'【入力用③】案件ごとCH（D案件以上）'!$N$5:$N$1048576,【表示用】各メンバーCH!$B10,'【入力用③】案件ごとCH（D案件以上）'!$H$5:$H$1048576,"A") -> 0.77 | ... O11: =SUMIFS('【入力用③】案件ごとCH（D案件以上）'!Z$5:Z$1048576,'【入力用③】案件ごとCH（D案件以上）'!$N$5:$N$1048576,【表示用】各メンバーCH!$B10,'【入力用③】案件ごとCH（D案件以上）'!$H$5:$H$1048576,"成立")+SUMIFS('【入力用③】案件ごとCH（D案件以上）'!Z$5:Z$1048576,'【入力用③】案件ごとCH（D案件以上）'!$N$5:$N$1048576,【表示用】各メンバーCH!$B10,'【入力用③】案件ごとCH（D案件以上）'!$H$5:$H$1048576,"A") -> 0.27
C12: ③GAP（②-①） | D12: =D11-D10 -> -0.2754 | E12: =E11-E10 -> -0.356 | F12: =F11-F10 -> -0.016 | G12: =G11-G10 -> -0.29 | H12: =H11-H10 -> 0.81 | I12: =I11-I10 -> 0.885 | J12: =J11-J10 -> 0.69 | K12: =K11-K10 -> -0.03 | ... O12: =O11-O10 -> -0.53
B13: 友祐 | C13: ①目標 | D13: 0.9 | E13: 0.9 | F13: 0.9 | G13: 0.9 | H13: 0.9 | I13: 0.9 | J13: 0.9 | K13: 0.9 | L13: 0.9 | M13: 0.9 | N13: 0.9 | O13: 0.9
C14: ②見積 | D14: =SUMIFS('【入力用③】案件ごとCH（D案件以上）'!O$5:O$1048576,'【入力用③】案件ごとCH（D案件以上）'!$N$5:$N$1048576,【表示用】各メンバーCH!$B13,'【入力用③】案件ごとCH（D案件以上）'!$H$5:$H$1048576,"成立")+SUMIFS('【入力用③】案件ごとCH（D案件以上）'!O$5:O$1048576,'【入力用③】案件ごとCH（D案件以上）'!$N$5:$N$1048576,【表示用】各メンバーCH!$B13,'【入力用③】案件ごとCH（D案件以上）'!$H$5:$H$1048576,"A") -> 1.97 | E14: =SUMIFS('【入力用③】案件ごとCH（D案件以上）'!P$5:P$1048576,'【入力用③】案件ごとCH（D案件以上）'!$N$5:$N$1048576,【表示用】各メンバーCH!$B13,'【入力用③】案件ごとCH（D案件以上）'!$H$5:$H$1048576,"成立")+SUMIFS('【入力用③】案件ごとCH（D案件以上）'!P$5:P$1048576,'【入力用③】案件ごとCH（D案件以上）'!$N$5:$N$1048576,【表示用】各メンバーCH!$B13,'【入力用③】案件ごとCH（D案件以上）'!$H$5:$H$1048576,"A") -> 2.205 | F14: =SUMIFS('【入力用③】案件ごとCH（D案件以上）'!Q$5:Q$1048576,'【入力用③】案件ごとCH（D案件以上）'!$N$5:$N$1048576,【表示用】各メンバーCH!$B13,'【入力用③】案件ごとCH（D案件以上）'!$H$5:$H$1048576,"成立")+SUMIFS('【入力用③】案件ごとCH（D案件以上）'!Q$5:Q$1048576,'【入力用③】案件ごとCH（D案件以上）'!$N$5:$N$1048576,【表示用】各メンバーCH!$B13,'【入力用③】案件ごとCH（D案件以上）'!$H$5:$H$1048576,"A") -> 2.202 | G14: =SUMIFS('【入力用③】案件ごとCH（D案件以上）'!R$5:R$1048576,'【入力用③】案件ごとCH（D案件以上）'!$N$5:$N$1048576,【表示用】各メンバーCH!$B13,'【入力用③】案件ごとCH（D案件以上）'!$H$5:$H$1048576,"成立")+SUMIFS('【入力用③】案件ごとCH（D案件以上）'!R$5:R$1048576,'【入力用③】案件ごとCH（D案件以上）'!$N$5:$N$1048576,【表示用】各メンバーCH!$B13,'【入力用③】案件ごとCH（D案件以上）'!$H$5:$H$1048576,"A") -> 0.9 | H14: =SUMIFS('【入力用③】案件ごとCH（D案件以上）'!S$5:S$1048576,'【入力用③】案件ごとCH（D案件以上）'!$N$5:$N$1048576,【表示用】各メンバーCH!$B13,'【入力用③】案件ごとCH（D案件以上）'!$H$5:$H$1048576,"成立")+SUMIFS('【入力用③】案件ごとCH（D案件以上）'!S$5:S$1048576,'【入力用③】案件ごとCH（D案件以上）'!$N$5:$N$1048576,【表示用】各メンバーCH!$B13,'【入力用③】案件ごとCH（D案件以上）'!$H$5:$H$1048576,"A") -> 1.46 | I14: =SUMIFS('【入力用③】案件ごとCH（D案件以上）'!T$5:T$1048576,'【入力用③】案件ごとCH（D案件以上）'!$N$5:$N$1048576,【表示用】各メンバーCH!$B13,'【入力用③】案件ごとCH（D案件以上）'!$H$5:$H$1048576,"成立")+SUMIFS('【入力用③】案件ごとCH（D案件以上）'!T$5:T$1048576,'【入力用③】案件ごとCH（D案件以上）'!$N$5:$N$1048576,【表示用】各メンバーCH!$B13,'【入力用③】案件ごとCH（D案件以上）'!$H$5:$H$1048576,"A") -> 1.27 | J14: =SUMIFS('【入力用③】案件ごとCH（D案件以上）'!U$5:U$1048576,'【入力用③】案件ごとCH（D案件以上）'!$N$5:$N$1048576,【表示用】各メンバーCH!$B13,'【入力用③】案件ごとCH（D案件以上）'!$H$5:$H$1048576,"成立")+SUMIFS('【入力用③】案件ごとCH（D案件以上）'!U$5:U$1048576,'【入力用③】案件ごとCH（D案件以上）'!$N$5:$N$1048576,【表示用】各メンバーCH!$B13,'【入力用③】案件ごとCH（D案件以上）'!$H$5:$H$1048576,"A") -> 0.635 | K14: =SUMIFS('【入力用③】案件ごとCH（D案件以上）'!V$5:V$1048576,'【入力用③】案件ごとCH（D案件以上）'!$N$5:$N$1048576,【表示用】各メンバーCH!$B13,'【入力用③】案件ごとCH（D案件以上）'!$H$5:$H$1048576,"成立")+SUMIFS('【入力用③】案件ごとCH（D案件以上）'!V$5:V$1048576,'【入力用③】案件ごとCH（D案件以上）'!$N$5:$N$1048576,【表示用】各メンバーCH!$B13,'【入力用③】案件ごとCH（D案件以上）'!$H$5:$H$1048576,"A") -> 0.045 | ... O14: =SUMIFS('【入力用③】案件ごとCH（D案件以上）'!Z$5:Z$1048576,'【入力用③】案件ごとCH（D案件以上）'!$N$5:$N$1048576,【表示用】各メンバーCH!$B13,'【入力用③】案件ごとCH（D案件以上）'!$H$5:$H$1048576,"成立")+SUMIFS('【入力用③】案件ごとCH（D案件以上）'!Z$5:Z$1048576,'【入力用③】案件ごとCH（D案件以上）'!$N$5:$N$1048576,【表示用】各メンバーCH!$B13,'【入力用③】案件ごとCH（D案件以上）'!$H$5:$H$1048576,"A") -> 0
C15: ③GAP（②-①） | D15: =D14-D13 -> 1.07 | E15: =E14-E13 -> 1.305 | F15: =F14-F13 -> 1.302 | G15: =G14-G13 -> 0 | H15: =H14-H13 -> 0.56 | I15: =I14-I13 -> 0.37 | J15: =J14-J13 -> -0.265 | K15: =K14-K13 -> -0.855 | ... O15: =O14-O13 -> -0.9
B16: 芹澤 | C16: ①目標 | D16: 0.9 | E16: 0.9 | F16: 0.9 | G16: 0.9 | H16: 0.9 | I16: 0.9 | J16: 0.9 | K16: 0.9 | L16: 0.9 | M16: 0.9 | N16: 0.9 | O16: 0.9
C17: ②見積 | D17: =SUMIFS('【入力用③】案件ごとCH（D案件以上）'!O$5:O$1048576,'【入力用③】案件ごとCH（D案件以上）'!$N$5:$N$1048576,【表示用】各メンバーCH!$B16,'【入力用③】案件ごとCH（D案件以上）'!$H$5:$H$1048576,"成立")+SUMIFS('【入力用③】案件ごとCH（D案件以上）'!O$5:O$1048576,'【入力用③】案件ごとCH（D案件以上）'!$N$5:$N$1048576,【表示用】各メンバーCH!$B16,'【入力用③】案件ごとCH（D案件以上）'!$H$5:$H$1048576,"A") -> 0.98 | E17: =SUMIFS('【入力用③】案件ごとCH（D案件以上）'!P$5:P$1048576,'【入力用③】案件ごとCH（D案件以上）'!$N$5:$N$1048576,【表示用】各メンバーCH!$B16,'【入力用③】案件ごとCH（D案件以上）'!$H$5:$H$1048576,"成立")+SUMIFS('【入力用③】案件ごとCH（D案件以上）'!P$5:P$1048576,'【入力用③】案件ごとCH（D案件以上）'!$N$5:$N$1048576,【表示用】各メンバーCH!$B16,'【入力用③】案件ごとCH（D案件以上）'!$H$5:$H$1048576,"A") -> 1.25 | F17: =SUMIFS('【入力用③】案件ごとCH（D案件以上）'!Q$5:Q$1048576,'【入力用③】案件ごとCH（D案件以上）'!$N$5:$N$1048576,【表示用】各メンバーCH!$B16,'【入力用③】案件ごとCH（D案件以上）'!$H$5:$H$1048576,"成立")+SUMIFS('【入力用③】案件ごとCH（D案件以上）'!Q$5:Q$1048576,'【入力用③】案件ごとCH（D案件以上）'!$N$5:$N$1048576,【表示用】各メンバーCH!$B16,'【入力用③】案件ごとCH（D案件以上）'!$H$5:$H$1048576,"A") -> 0.9 | G17: =SUMIFS('【入力用③】案件ごとCH（D案件以上）'!R$5:R$1048576,'【入力用③】案件ごとCH（D案件以上）'!$N$5:$N$1048576,【表示用】各メンバーCH!$B16,'【入力用③】案件ごとCH（D案件以上）'!$H$5:$H$1048576,"成立")+SUMIFS('【入力用③】案件ごとCH（D案件以上）'!R$5:R$1048576,'【入力用③】案件ごとCH（D案件以上）'!$N$5:$N$1048576,【表示用】各メンバーCH!$B16,'【入力用③】案件ごとCH（D案件以上）'!$H$5:$H$1048576,"A") -> 1.183 | H17: =SUMIFS('【入力用③】案件ごとCH（D案件以上）'!S$5:S$1048576,'【入力用③】案件ごとCH（D案件以上）'!$N$5:$N$1048576,【表示用】各メンバーCH!$B16,'【入力用③】案件ごとCH（D案件以上）'!$H$5:$H$1048576,"成立")+SUMIFS('【入力用③】案件ごとCH（D案件以上）'!S$5:S$1048576,'【入力用③】案件ごとCH（D案件以上）'!$N$5:$N$1048576,【表示用】各メンバーCH!$B16,'【入力用③】案件ごとCH（D案件以上）'!$H$5:$H$1048576,"A") -> 0.4 | I17: =SUMIFS('【入力用③】案件ごとCH（D案件以上）'!T$5:T$1048576,'【入力用③】案件ごとCH（D案件以上）'!$N$5:$N$1048576,【表示用】各メンバーCH!$B16,'【入力用③】案件ごとCH（D案件以上）'!$H$5:$H$1048576,"成立")+SUMIFS('【入力用③】案件ごとCH（D案件以上）'!T$5:T$1048576,'【入力用③】案件ごとCH（D案件以上）'!$N$5:$N$1048576,【表示用】各メンバーCH!$B16,'【入力用③】案件ごとCH（D案件以上）'!$H$5:$H$1048576,"A") -> 0.55 | J17: =SUMIFS('【入力用③】案件ごとCH（D案件以上）'!U$5:U$1048576,'【入力用③】案件ごとCH（D案件以上）'!$N$5:$N$1048576,【表示用】各メンバーCH!$B16,'【入力用③】案件ごとCH（D案件以上）'!$H$5:$H$1048576,"成立")+SUMIFS('【入力用③】案件ごとCH（D案件以上）'!U$5:U$1048576,'【入力用③】案件ごとCH（D案件以上）'!$N$5:$N$1048576,【表示用】各メンバーCH!$B16,'【入力用③】案件ごとCH（D案件以上）'!$H$5:$H$1048576,"A") -> 0.1 | K17: =SUMIFS('【入力用③】案件ごとCH（D案件以上）'!V$5:V$1048576,'【入力用③】案件ごとCH（D案件以上）'!$N$5:$N$1048576,【表示用】各メンバーCH!$B16,'【入力用③】案件ごとCH（D案件以上）'!$H$5:$H$1048576,"成立")+SUMIFS('【入力用③】案件ごとCH（D案件以上）'!V$5:V$1048576,'【入力用③】案件ごとCH（D案件以上）'!$N$5:$N$1048576,【表示用】各メンバーCH!$B16,'【入力用③】案件ごとCH（D案件以上）'!$H$5:$H$1048576,"A") -> 0 | ... O17: =SUMIFS('【入力用③】案件ごとCH（D案件以上）'!Z$5:Z$1048576,'【入力用③】案件ごとCH（D案件以上）'!$N$5:$N$1048576,【表示用】各メンバーCH!$B16,'【入力用③】案件ごとCH（D案件以上）'!$H$5:$H$1048576,"成立")+SUMIFS('【入力用③】案件ごとCH（D案件以上）'!Z$5:Z$1048576,'【入力用③】案件ごとCH（D案件以上）'!$N$5:$N$1048576,【表示用】各メンバーCH!$B16,'【入力用③】案件ごとCH（D案件以上）'!$H$5:$H$1048576,"A") -> 0
C18: ③GAP（②-①） | D18: =D17-D16 -> 0.08 | E18: =E17-E16 -> 0.35 | F18: =F17-F16 -> 0 | G18: =G17-G16 -> 0.283 | H18: =H17-H16 -> -0.5 | I18: =I17-I16 -> -0.35 | J18: =J17-J16 -> -0.8 | K18: =K17-K16 -> -0.9 | ... O18: =O17-O16 -> -0.9
B19: 弓本 | C19: ①目標 | D19: 0.9 | E19: 0.9 | F19: 0.9 | G19: 0.9 | H19: 0.9 | I19: 0.9 | J19: 0.9 | K19: 0.9 | L19: 0.9 | M19: 0.9 | N19: 0.9 | O19: 0.9
C20: ②見積 | D20: =SUMIFS('【入力用③】案件ごとCH（D案件以上）'!O$5:O$1048576,'【入力用③】案件ごとCH（D案件以上）'!$N$5:$N$1048576,【表示用】各メンバーCH!$B19,'【入力用③】案件ごとCH（D案件以上）'!$H$5:$H$1048576,"成立")+SUMIFS('【入力用③】案件ごとCH（D案件以上）'!O$5:O$1048576,'【入力用③】案件ごとCH（D案件以上）'!$N$5:$N$1048576,【表示用】各メンバーCH!$B19,'【入力用③】案件ごとCH（D案件以上）'!$H$5:$H$1048576,"A") -> 0.75 | E20: =SUMIFS('【入力用③】案件ごとCH（D案件以上）'!P$5:P$1048576,'【入力用③】案件ごとCH（D案件以上）'!$N$5:$N$1048576,【表示用】各メンバーCH!$B19,'【入力用③】案件ごとCH（D案件以上）'!$H$5:$H$1048576,"成立")+SUMIFS('【入力用③】案件ごとCH（D案件以上）'!P$5:P$1048576,'【入力用③】案件ごとCH（D案件以上）'!$N$5:$N$1048576,【表示用】各メンバーCH!$B19,'【入力用③】案件ごとCH（D案件以上）'!$H$5:$H$1048576,"A") -> 0.55 | F20: =SUMIFS('【入力用③】案件ごとCH（D案件以上）'!Q$5:Q$1048576,'【入力用③】案件ごとCH（D案件以上）'!$N$5:$N$1048576,【表示用】各メンバーCH!$B19,'【入力用③】案件ごとCH（D案件以上）'!$H$5:$H$1048576,"成立")+SUMIFS('【入力用③】案件ごとCH（D案件以上）'!Q$5:Q$1048576,'【入力用③】案件ごとCH（D案件以上）'!$N$5:$N$1048576,【表示用】各メンバーCH!$B19,'【入力用③】案件ごとCH（D案件以上）'!$H$5:$H$1048576,"A") -> 1.1 | G20: =SUMIFS('【入力用③】案件ごとCH（D案件以上）'!R$5:R$1048576,'【入力用③】案件ごとCH（D案件以上）'!$N$5:$N$1048576,【表示用】各メンバーCH!$B19,'【入力用③】案件ごとCH（D案件以上）'!$H$5:$H$1048576,"成立")+SUMIFS('【入力用③】案件ごとCH（D案件以上）'!R$5:R$1048576,'【入力用③】案件ごとCH（D案件以上）'!$N$5:$N$1048576,【表示用】各メンバーCH!$B19,'【入力用③】案件ごとCH（D案件以上）'!$H$5:$H$1048576,"A") -> 0.85 | H20: =SUMIFS('【入力用③】案件ごとCH（D案件以上）'!S$5:S$1048576,'【入力用③】案件ごとCH（D案件以上）'!$N$5:$N$1048576,【表示用】各メンバーCH!$B19,'【入力用③】案件ごとCH（D案件以上）'!$H$5:$H$1048576,"成立")+SUMIFS('【入力用③】案件ごとCH（D案件以上）'!S$5:S$1048576,'【入力用③】案件ごとCH（D案件以上）'!$N$5:$N$1048576,【表示用】各メンバーCH!$B19,'【入力用③】案件ごとCH（D案件以上）'!$H$5:$H$1048576,"A") -> 0.85 | I20: =SUMIFS('【入力用③】案件ごとCH（D案件以上）'!T$5:T$1048576,'【入力用③】案件ごとCH（D案件以上）'!$N$5:$N$1048576,【表示用】各メンバーCH!$B19,'【入力用③】案件ごとCH（D案件以上）'!$H$5:$H$1048576,"成立")+SUMIFS('【入力用③】案件ごとCH（D案件以上）'!T$5:T$1048576,'【入力用③】案件ごとCH（D案件以上）'!$N$5:$N$1048576,【表示用】各メンバーCH!$B19,'【入力用③】案件ごとCH（D案件以上）'!$H$5:$H$1048576,"A") -> 0.3 | J20: =SUMIFS('【入力用③】案件ごとCH（D案件以上）'!U$5:U$1048576,'【入力用③】案件ごとCH（D案件以上）'!$N$5:$N$1048576,【表示用】各メンバーCH!$B19,'【入力用③】案件ごとCH（D案件以上）'!$H$5:$H$1048576,"成立")+SUMIFS('【入力用③】案件ごとCH（D案件以上）'!U$5:U$1048576,'【入力用③】案件ごとCH（D案件以上）'!$N$5:$N$1048576,【表示用】各メンバーCH!$B19,'【入力用③】案件ごとCH（D案件以上）'!$H$5:$H$1048576,"A") -> 0 | K20: =SUMIFS('【入力用③】案件ごとCH（D案件以上）'!V$5:V$1048576,'【入力用③】案件ごとCH（D案件以上）'!$N$5:$N$1048576,【表示用】各メンバーCH!$B19,'【入力用③】案件ごとCH（D案件以上）'!$H$5:$H$1048576,"成立")+SUMIFS('【入力用③】案件ごとCH（D案件以上）'!V$5:V$1048576,'【入力用③】案件ごとCH（D案件以上）'!$N$5:$N$1048576,【表示用】各メンバーCH!$B19,'【入力用③】案件ごとCH（D案件以上）'!$H$5:$H$1048576,"A") -> 0 | ... O20: =SUMIFS('【入力用③】案件ごとCH（D案件以上）'!Z$5:Z$1048576,'【入力用③】案件ごとCH（D案件以上）'!$N$5:$N$1048576,【表示用】各メンバーCH!$B19,'【入力用③】案件ごとCH（D案件以上）'!$H$5:$H$1048576,"成立")+SUMIFS('【入力用③】案件ごとCH（D案件以上）'!Z$5:Z$1048576,'【入力用③】案件ごとCH（D案件以上）'!$N$5:$N$1048576,【表示用】各メンバーCH!$B19,'【入力用③】案件ごとCH（D案件以上）'!$H$5:$H$1048576,"A") -> 0
C21: ③GAP（②-①） | D21: =D20-D19 -> -0.15 | E21: =E20-E19 -> -0.35 | F21: =F20-F19 -> 0.2 | G21: =G20-G19 -> -0.05 | H21: =H20-H19 -> -0.05 | I21: =I20-I19 -> -0.6 | J21: =J20-J19 -> -0.9 | K21: =K20-K19 -> -0.9 | ... O21: =O20-O19 -> -0.9
B22: 丸田 | C22: ①目標 | D22: 0.9 | E22: 0.9 | F22: 0.9 | G22: 0.9 | H22: 0.9 | I22: 0.9 | J22: 0.9 | K22: 0.9 | L22: 0.9 | M22: 0.9 | N22: 0.9 | O22: 0.9
C23: ②見積 | D23: =SUMIFS('【入力用③】案件ごとCH（D案件以上）'!O$5:O$1048576,'【入力用③】案件ごとCH（D案件以上）'!$N$5:$N$1048576,【表示用】各メンバーCH!$B22,'【入力用③】案件ごとCH（D案件以上）'!$H$5:$H$1048576,"成立")+SUMIFS('【入力用③】案件ごとCH（D案件以上）'!O$5:O$1048576,'【入力用③】案件ごとCH（D案件以上）'!$N$5:$N$1048576,【表示用】各メンバーCH!$B22,'【入力用③】案件ごとCH（D案件以上）'!$H$5:$H$1048576,"A") -> 1.1659 | E23: =SUMIFS('【入力用③】案件ごとCH（D案件以上）'!P$5:P$1048576,'【入力用③】案件ごとCH（D案件以上）'!$N$5:$N$1048576,【表示用】各メンバーCH!$B22,'【入力用③】案件ごとCH（D案件以上）'!$H$5:$H$1048576,"成立")+SUMIFS('【入力用③】案件ごとCH（D案件以上）'!P$5:P$1048576,'【入力用③】案件ごとCH（D案件以上）'!$N$5:$N$1048576,【表示用】各メンバーCH!$B22,'【入力用③】案件ごとCH（D案件以上）'!$H$5:$H$1048576,"A") -> 2.2 | F23: =SUMIFS('【入力用③】案件ごとCH（D案件以上）'!Q$5:Q$1048576,'【入力用③】案件ごとCH（D案件以上）'!$N$5:$N$1048576,【表示用】各メンバーCH!$B22,'【入力用③】案件ごとCH（D案件以上）'!$H$5:$H$1048576,"成立")+SUMIFS('【入力用③】案件ごとCH（D案件以上）'!Q$5:Q$1048576,'【入力用③】案件ごとCH（D案件以上）'!$N$5:$N$1048576,【表示用】各メンバーCH!$B22,'【入力用③】案件ごとCH（D案件以上）'!$H$5:$H$1048576,"A") -> 1.35 | G23: =SUMIFS('【入力用③】案件ごとCH（D案件以上）'!R$5:R$1048576,'【入力用③】案件ごとCH（D案件以上）'!$N$5:$N$1048576,【表示用】各メンバーCH!$B22,'【入力用③】案件ごとCH（D案件以上）'!$H$5:$H$1048576,"成立")+SUMIFS('【入力用③】案件ごとCH（D案件以上）'!R$5:R$1048576,'【入力用③】案件ごとCH（D案件以上）'!$N$5:$N$1048576,【表示用】各メンバーCH!$B22,'【入力用③】案件ごとCH（D案件以上）'!$H$5:$H$1048576,"A") -> 1.64 | H23: =SUMIFS('【入力用③】案件ごとCH（D案件以上）'!S$5:S$1048576,'【入力用③】案件ごとCH（D案件以上）'!$N$5:$N$1048576,【表示用】各メンバーCH!$B22,'【入力用③】案件ごとCH（D案件以上）'!$H$5:$H$1048576,"成立")+SUMIFS('【入力用③】案件ごとCH（D案件以上）'!S$5:S$1048576,'【入力用③】案件ごとCH（D案件以上）'!$N$5:$N$1048576,【表示用】各メンバーCH!$B22,'【入力用③】案件ごとCH（D案件以上）'!$H$5:$H$1048576,"A") -> 0.52 | I23: =SUMIFS('【入力用③】案件ごとCH（D案件以上）'!T$5:T$1048576,'【入力用③】案件ごとCH（D案件以上）'!$N$5:$N$1048576,【表示用】各メンバーCH!$B22,'【入力用③】案件ごとCH（D案件以上）'!$H$5:$H$1048576,"成立")+SUMIFS('【入力用③】案件ごとCH（D案件以上）'!T$5:T$1048576,'【入力用③】案件ごとCH（D案件以上）'!$N$5:$N$1048576,【表示用】各メンバーCH!$B22,'【入力用③】案件ごとCH（D案件以上）'!$H$5:$H$1048576,"A") -> 0.8 | J23: =SUMIFS('【入力用③】案件ごとCH（D案件以上）'!U$5:U$1048576,'【入力用③】案件ごとCH（D案件以上）'!$N$5:$N$1048576,【表示用】各メンバーCH!$B22,'【入力用③】案件ごとCH（D案件以上）'!$H$5:$H$1048576,"成立")+SUMIFS('【入力用③】案件ごとCH（D案件以上）'!U$5:U$1048576,'【入力用③】案件ごとCH（D案件以上）'!$N$5:$N$1048576,【表示用】各メンバーCH!$B22,'【入力用③】案件ごとCH（D案件以上）'!$H$5:$H$1048576,"A") -> 0.8 | K23: =SUMIFS('【入力用③】案件ごとCH（D案件以上）'!V$5:V$1048576,'【入力用③】案件ごとCH（D案件以上）'!$N$5:$N$1048576,【表示用】各メンバーCH!$B22,'【入力用③】案件ごとCH（D案件以上）'!$H$5:$H$1048576,"成立")+SUMIFS('【入力用③】案件ごとCH（D案件以上）'!V$5:V$1048576,'【入力用③】案件ごとCH（D案件以上）'!$N$5:$N$1048576,【表示用】各メンバーCH!$B22,'【入力用③】案件ごとCH（D案件以上）'!$H$5:$H$1048576,"A") -> 0.4 | ... O23: =SUMIFS('【入力用③】案件ごとCH（D案件以上）'!Z$5:Z$1048576,'【入力用③】案件ごとCH（D案件以上）'!$N$5:$N$1048576,【表示用】各メンバーCH!$B22,'【入力用③】案件ごとCH（D案件以上）'!$H$5:$H$1048576,"成立")+SUMIFS('【入力用③】案件ごとCH（D案件以上）'!Z$5:Z$1048576,'【入力用③】案件ごとCH（D案件以上）'!$N$5:$N$1048576,【表示用】各メンバーCH!$B22,'【入力用③】案件ごとCH（D案件以上）'!$H$5:$H$1048576,"A") -> 0
C24: ③GAP（②-①） | D24: =D23-D22 -> 0.2659 | E24: =E23-E22 -> 1.3 | F24: =F23-F22 -> 0.45 | G24: =G23-G22 -> 0.74 | H24: =H23-H22 -> -0.38 | I24: =I23-I22 -> -0.1 | J24: =J23-J22 -> -0.1 | K24: =K23-K22 -> -0.5 | ... O24: =O23-O22 -> -0.9
B25: 加藤 | C25: ①目標 | D25: 0.9 | E25: 0.9 | F25: 0.9 | G25: 0.9 | H25: 0.9 | I25: 0.9 | J25: 0.9 | K25: 0.9 | L25: 0.9 | M25: 0.9 | N25: 0.9 | O25: 0.9
C26: ②見積 | D26: =SUMIFS('【入力用③】案件ごとCH（D案件以上）'!O$5:O$1048576,'【入力用③】案件ごとCH（D案件以上）'!$N$5:$N$1048576,【表示用】各メンバーCH!$B25,'【入力用③】案件ごとCH（D案件以上）'!$H$5:$H$1048576,"成立")+SUMIFS('【入力用③】案件ごとCH（D案件以上）'!O$5:O$1048576,'【入力用③】案件ごとCH（D案件以上）'!$N$5:$N$1048576,【表示用】各メンバーCH!$B25,'【入力用③】案件ごとCH（D案件以上）'!$H$5:$H$1048576,"A") -> 0.75 | E26: =SUMIFS('【入力用③】案件ごとCH（D案件以上）'!P$5:P$1048576,'【入力用③】案件ごとCH（D案件以上）'!$N$5:$N$1048576,【表示用】各メンバーCH!$B25,'【入力用③】案件ごとCH（D案件以上）'!$H$5:$H$1048576,"成立")+SUMIFS('【入力用③】案件ごとCH（D案件以上）'!P$5:P$1048576,'【入力用③】案件ごとCH（D案件以上）'!$N$5:$N$1048576,【表示用】各メンバーCH!$B25,'【入力用③】案件ごとCH（D案件以上）'!$H$5:$H$1048576,"A") -> 0.97 | F26: =SUMIFS('【入力用③】案件ごとCH（D案件以上）'!Q$5:Q$1048576,'【入力用③】案件ごとCH（D案件以上）'!$N$5:$N$1048576,【表示用】各メンバーCH!$B25,'【入力用③】案件ごとCH（D案件以上）'!$H$5:$H$1048576,"成立")+SUMIFS('【入力用③】案件ごとCH（D案件以上）'!Q$5:Q$1048576,'【入力用③】案件ごとCH（D案件以上）'!$N$5:$N$1048576,【表示用】各メンバーCH!$B25,'【入力用③】案件ごとCH（D案件以上）'!$H$5:$H$1048576,"A") -> 0.69 | G26: =SUMIFS('【入力用③】案件ごとCH（D案件以上）'!R$5:R$1048576,'【入力用③】案件ごとCH（D案件以上）'!$N$5:$N$1048576,【表示用】各メンバーCH!$B25,'【入力用③】案件ごとCH（D案件以上）'!$H$5:$H$1048576,"成立")+SUMIFS('【入力用③】案件ごとCH（D案件以上）'!R$5:R$1048576,'【入力用③】案件ごとCH（D案件以上）'!$N$5:$N$1048576,【表示用】各メンバーCH!$B25,'【入力用③】案件ごとCH（D案件以上）'!$H$5:$H$1048576,"A") -> 0.75 | H26: =SUMIFS('【入力用③】案件ごとCH（D案件以上）'!S$5:S$1048576,'【入力用③】案件ごとCH（D案件以上）'!$N$5:$N$1048576,【表示用】各メンバーCH!$B25,'【入力用③】案件ごとCH（D案件以上）'!$H$5:$H$1048576,"成立")+SUMIFS('【入力用③】案件ごとCH（D案件以上）'!S$5:S$1048576,'【入力用③】案件ごとCH（D案件以上）'!$N$5:$N$1048576,【表示用】各メンバーCH!$B25,'【入力用③】案件ごとCH（D案件以上）'!$H$5:$H$1048576,"A") -> 0.12 | I26: =SUMIFS('【入力用③】案件ごとCH（D案件以上）'!T$5:T$1048576,'【入力用③】案件ごとCH（D案件以上）'!$N$5:$N$1048576,【表示用】各メンバーCH!$B25,'【入力用③】案件ごとCH（D案件以上）'!$H$5:$H$1048576,"成立")+SUMIFS('【入力用③】案件ごとCH（D案件以上）'!T$5:T$1048576,'【入力用③】案件ごとCH（D案件以上）'!$N$5:$N$1048576,【表示用】各メンバーCH!$B25,'【入力用③】案件ごとCH（D案件以上）'!$H$5:$H$1048576,"A") -> 0.75 | J26: =SUMIFS('【入力用③】案件ごとCH（D案件以上）'!U$5:U$1048576,'【入力用③】案件ごとCH（D案件以上）'!$N$5:$N$1048576,【表示用】各メンバーCH!$B25,'【入力用③】案件ごとCH（D案件以上）'!$H$5:$H$1048576,"成立")+SUMIFS('【入力用③】案件ごとCH（D案件以上）'!U$5:U$1048576,'【入力用③】案件ごとCH（D案件以上）'!$N$5:$N$1048576,【表示用】各メンバーCH!$B25,'【入力用③】案件ごとCH（D案件以上）'!$H$5:$H$1048576,"A") -> 0.695 | K26: =SUMIFS('【入力用③】案件ごとCH（D案件以上）'!V$5:V$1048576,'【入力用③】案件ごとCH（D案件以上）'!$N$5:$N$1048576,【表示用】各メンバーCH!$B25,'【入力用③】案件ごとCH（D案件以上）'!$H$5:$H$1048576,"成立")+SUMIFS('【入力用③】案件ごとCH（D案件以上）'!V$5:V$1048576,'【入力用③】案件ごとCH（D案件以上）'!$N$5:$N$1048576,【表示用】各メンバーCH!$B25,'【入力用③】案件ごとCH（D案件以上）'!$H$5:$H$1048576,"A") -> 0.4 | ... O26: =SUMIFS('【入力用③】案件ごとCH（D案件以上）'!Z$5:Z$1048576,'【入力用③】案件ごとCH（D案件以上）'!$N$5:$N$1048576,【表示用】各メンバーCH!$B25,'【入力用③】案件ごとCH（D案件以上）'!$H$5:$H$1048576,"成立")+SUMIFS('【入力用③】案件ごとCH（D案件以上）'!Z$5:Z$1048576,'【入力用③】案件ごとCH（D案件以上）'!$N$5:$N$1048576,【表示用】各メンバーCH!$B25,'【入力用③】案件ごとCH（D案件以上）'!$H$5:$H$1048576,"A") -> 0
C27: ③GAP（②-①） | D27: =D26-D25 -> -0.15 | E27: =E26-E25 -> 0.07 | F27: =F26-F25 -> -0.21 | G27: =G26-G25 -> -0.15 | H27: =H26-H25 -> -0.78 | I27: =I26-I25 -> -0.15 | J27: =J26-J25 -> -0.205 | K27: =K26-K25 -> -0.5 | ... O27: =O26-O25 -> -0.9
B28: 古藤 | C28: ①目標 | D28: 0.8 | E28: 0.8 | F28: 0.8 | G28: 0.8 | H28: 0.8 | I28: 0.8 | J28: 0.8 | K28: 0.8 | L28: 0.8 | M28: 0.8 | N28: 0.8 | O28: 0.8
C29: ②見積 | D29: =SUMIFS('【入力用③】案件ごとCH（D案件以上）'!O$5:O$1048576,'【入力用③】案件ごとCH（D案件以上）'!$N$5:$N$1048576,【表示用】各メンバーCH!$B28,'【入力用③】案件ごとCH（D案件以上）'!$H$5:$H$1048576,"成立")+SUMIFS('【入力用③】案件ごとCH（D案件以上）'!O$5:O$1048576,'【入力用③】案件ごとCH（D案件以上）'!$N$5:$N$1048576,【表示用】各メンバーCH!$B28,'【入力用③】案件ごとCH（D案件以上）'!$H$5:$H$1048576,"A") -> 0 | E29: =SUMIFS('【入力用③】案件ごとCH（D案件以上）'!P$5:P$1048576,'【入力用③】案件ごとCH（D案件以上）'!$N$5:$N$1048576,【表示用】各メンバーCH!$B28,'【入力用③】案件ごとCH（D案件以上）'!$H$5:$H$1048576,"成立")+SUMIFS('【入力用③】案件ごとCH（D案件以上）'!P$5:P$1048576,'【入力用③】案件ごとCH（D案件以上）'!$N$5:$N$1048576,【表示用】各メンバーCH!$B28,'【入力用③】案件ごとCH（D案件以上）'!$H$5:$H$1048576,"A") -> 0 | F29: =SUMIFS('【入力用③】案件ごとCH（D案件以上）'!Q$5:Q$1048576,'【入力用③】案件ごとCH（D案件以上）'!$N$5:$N$1048576,【表示用】各メンバーCH!$B28,'【入力用③】案件ごとCH（D案件以上）'!$H$5:$H$1048576,"成立")+SUMIFS('【入力用③】案件ごとCH（D案件以上）'!Q$5:Q$1048576,'【入力用③】案件ごとCH（D案件以上）'!$N$5:$N$1048576,【表示用】各メンバーCH!$B28,'【入力用③】案件ごとCH（D案件以上）'!$H$5:$H$1048576,"A") -> 0 | G29: =SUMIFS('【入力用③】案件ごとCH（D案件以上）'!R$5:R$1048576,'【入力用③】案件ごとCH（D案件以上）'!$N$5:$N$1048576,【表示用】各メンバーCH!$B28,'【入力用③】案件ごとCH（D案件以上）'!$H$5:$H$1048576,"成立")+SUMIFS('【入力用③】案件ごとCH（D案件以上）'!R$5:R$1048576,'【入力用③】案件ごとCH（D案件以上）'!$N$5:$N$1048576,【表示用】各メンバーCH!$B28,'【入力用③】案件ごとCH（D案件以上）'!$H$5:$H$1048576,"A") -> 0 | H29: =SUMIFS('【入力用③】案件ごとCH（D案件以上）'!S$5:S$1048576,'【入力用③】案件ごとCH（D案件以上）'!$N$5:$N$1048576,【表示用】各メンバーCH!$B28,'【入力用③】案件ごとCH（D案件以上）'!$H$5:$H$1048576,"成立")+SUMIFS('【入力用③】案件ごとCH（D案件以上）'!S$5:S$1048576,'【入力用③】案件ごとCH（D案件以上）'!$N$5:$N$1048576,【表示用】各メンバーCH!$B28,'【入力用③】案件ごとCH（D案件以上）'!$H$5:$H$1048576,"A") -> 0 | I29: =SUMIFS('【入力用③】案件ごとCH（D案件以上）'!T$5:T$1048576,'【入力用③】案件ごとCH（D案件以上）'!$N$5:$N$1048576,【表示用】各メンバーCH!$B28,'【入力用③】案件ごとCH（D案件以上）'!$H$5:$H$1048576,"成立")+SUMIFS('【入力用③】案件ごとCH（D案件以上）'!T$5:T$1048576,'【入力用③】案件ごとCH（D案件以上）'!$N$5:$N$1048576,【表示用】各メンバーCH!$B28,'【入力用③】案件ごとCH（D案件以上）'!$H$5:$H$1048576,"A") -> 0.7 | J29: =SUMIFS('【入力用③】案件ごとCH（D案件以上）'!U$5:U$1048576,'【入力用③】案件ごとCH（D案件以上）'!$N$5:$N$1048576,【表示用】各メンバーCH!$B28,'【入力用③】案件ごとCH（D案件以上）'!$H$5:$H$1048576,"成立")+SUMIFS('【入力用③】案件ごとCH（D案件以上）'!U$5:U$1048576,'【入力用③】案件ごとCH（D案件以上）'!$N$5:$N$1048576,【表示用】各メンバーCH!$B28,'【入力用③】案件ごとCH（D案件以上）'!$H$5:$H$1048576,"A") -> 1 | K29: =SUMIFS('【入力用③】案件ごとCH（D案件以上）'!V$5:V$1048576,'【入力用③】案件ごとCH（D案件以上）'!$N$5:$N$1048576,【表示用】各メンバーCH!$B28,'【入力用③】案件ごとCH（D案件以上）'!$H$5:$H$1048576,"成立")+SUMIFS('【入力用③】案件ごとCH（D案件以上）'!V$5:V$1048576,'【入力用③】案件ごとCH（D案件以上）'!$N$5:$N$1048576,【表示用】各メンバーCH!$B28,'【入力用③】案件ごとCH（D案件以上）'!$H$5:$H$1048576,"A") -> 0 | ... O29: =SUMIFS('【入力用③】案件ごとCH（D案件以上）'!Z$5:Z$1048576,'【入力用③】案件ごとCH（D案件以上）'!$N$5:$N$1048576,【表示用】各メンバーCH!$B28,'【入力用③】案件ごとCH（D案件以上）'!$H$5:$H$1048576,"成立")+SUMIFS('【入力用③】案件ごとCH（D案件以上）'!Z$5:Z$1048576,'【入力用③】案件ごとCH（D案件以上）'!$N$5:$N$1048576,【表示用】各メンバーCH!$B28,'【入力用③】案件ごとCH（D案件以上）'!$H$5:$H$1048576,"A") -> 0
C30: ③GAP（②-①） | D30: =D29-D28 -> -0.8 | E30: =E29-E28 -> -0.8 | F30: =F29-F28 -> -0.8 | G30: =G29-G28 -> -0.8 | H30: =H29-H28 -> -0.8 | I30: =I29-I28 -> -0.1 | J30: =J29-J28 -> 0.2 | K30: =K29-K28 -> -0.8 | ... O30: =O29-O28 -> -0.8
B31: 小野寺 | C31: ①目標
C32: ②見積 | D32: =SUMIFS('【入力用③】案件ごとCH（D案件以上）'!O$5:O$1048576,'【入力用③】案件ごとCH（D案件以上）'!$N$5:$N$1048576,【表示用】各メンバーCH!$B31,'【入力用③】案件ごとCH（D案件以上）'!$H$5:$H$1048576,"成立")+SUMIFS('【入力用③】案件ごとCH（D案件以上）'!O$5:O$1048576,'【入力用③】案件ごとCH（D案件以上）'!$N$5:$N$1048576,【表示用】各メンバーCH!$B31,'【入力用③】案件ごとCH（D案件以上）'!$H$5:$H$1048576,"A") -> 0 | E32: =SUMIFS('【入力用③】案件ごとCH（D案件以上）'!P$5:P$1048576,'【入力用③】案件ごとCH（D案件以上）'!$N$5:$N$1048576,【表示用】各メンバーCH!$B31,'【入力用③】案件ごとCH（D案件以上）'!$H$5:$H$1048576,"成立")+SUMIFS('【入力用③】案件ごとCH（D案件以上）'!P$5:P$1048576,'【入力用③】案件ごとCH（D案件以上）'!$N$5:$N$1048576,【表示用】各メンバーCH!$B31,'【入力用③】案件ごとCH（D案件以上）'!$H$5:$H$1048576,"A") -> 0 | F32: =SUMIFS('【入力用③】案件ごとCH（D案件以上）'!Q$5:Q$1048576,'【入力用③】案件ごとCH（D案件以上）'!$N$5:$N$1048576,【表示用】各メンバーCH!$B31,'【入力用③】案件ごとCH（D案件以上）'!$H$5:$H$1048576,"成立")+SUMIFS('【入力用③】案件ごとCH（D案件以上）'!Q$5:Q$1048576,'【入力用③】案件ごとCH（D案件以上）'!$N$5:$N$1048576,【表示用】各メンバーCH!$B31,'【入力用③】案件ごとCH（D案件以上）'!$H$5:$H$1048576,"A") -> 0 | G32: =SUMIFS('【入力用③】案件ごとCH（D案件以上）'!R$5:R$1048576,'【入力用③】案件ごとCH（D案件以上）'!$N$5:$N$1048576,【表示用】各メンバーCH!$B31,'【入力用③】案件ごとCH（D案件以上）'!$H$5:$H$1048576,"成立")+SUMIFS('【入力用③】案件ごとCH（D案件以上）'!R$5:R$1048576,'【入力用③】案件ごとCH（D案件以上）'!$N$5:$N$1048576,【表示用】各メンバーCH!$B31,'【入力用③】案件ごとCH（D案件以上）'!$H$5:$H$1048576,"A") -> 0 | H32: =SUMIFS('【入力用③】案件ごとCH（D案件以上）'!S$5:S$1048576,'【入力用③】案件ごとCH（D案件以上）'!$N$5:$N$1048576,【表示用】各メンバーCH!$B31,'【入力用③】案件ごとCH（D案件以上）'!$H$5:$H$1048576,"成立")+SUMIFS('【入力用③】案件ごとCH（D案件以上）'!S$5:S$1048576,'【入力用③】案件ごとCH（D案件以上）'!$N$5:$N$1048576,【表示用】各メンバーCH!$B31,'【入力用③】案件ごとCH（D案件以上）'!$H$5:$H$1048576,"A") -> 0 | I32: =SUMIFS('【入力用③】案件ごとCH（D案件以上）'!T$5:T$1048576,'【入力用③】案件ごとCH（D案件以上）'!$N$5:$N$1048576,【表示用】各メンバーCH!$B31,'【入力用③】案件ごとCH（D案件以上）'!$H$5:$H$1048576,"成立")+SUMIFS('【入力用③】案件ごとCH（D案件以上）'!T$5:T$1048576,'【入力用③】案件ごとCH（D案件以上）'!$N$5:$N$1048576,【表示用】各メンバーCH!$B31,'【入力用③】案件ごとCH（D案件以上）'!$H$5:$H$1048576,"A") -> 0 | J32: =SUMIFS('【入力用③】案件ごとCH（D案件以上）'!U$5:U$1048576,'【入力用③】案件ごとCH（D案件以上）'!$N$5:$N$1048576,【表示用】各メンバーCH!$B31,'【入力用③】案件ごとCH（D案件以上）'!$H$5:$H$1048576,"成立")+SUMIFS('【入力用③】案件ごとCH（D案件以上）'!U$5:U$1048576,'【入力用③】案件ごとCH（D案件以上）'!$N$5:$N$1048576,【表示用】各メンバーCH!$B31,'【入力用③】案件ごとCH（D案件以上）'!$H$5:$H$1048576,"A") -> 0 | K32: =SUMIFS('【入力用③】案件ごとCH（D案件以上）'!V$5:V$1048576,'【入力用③】案件ごとCH（D案件以上）'!$N$5:$N$1048576,【表示用】各メンバーCH!$B31,'【入力用③】案件ごとCH（D案件以上）'!$H$5:$H$1048576,"成立")+SUMIFS('【入力用③】案件ごとCH（D案件以上）'!V$5:V$1048576,'【入力用③】案件ごとCH（D案件以上）'!$N$5:$N$1048576,【表示用】各メンバーCH!$B31,'【入力用③】案件ごとCH（D案件以上）'!$H$5:$H$1048576,"A") -> 0 | ... O32: =SUMIFS('【入力用③】案件ごとCH（D案件以上）'!Z$5:Z$1048576,'【入力用③】案件ごとCH（D案件以上）'!$N$5:$N$1048576,【表示用】各メンバーCH!$B31,'【入力用③】案件ごとCH（D案件以上）'!$H$5:$H$1048576,"成立")+SUMIFS('【入力用③】案件ごとCH（D案件以上）'!Z$5:Z$1048576,'【入力用③】案件ごとCH（D案件以上）'!$N$5:$N$1048576,【表示用】各メンバーCH!$B31,'【入力用③】案件ごとCH（D案件以上）'!$H$5:$H$1048576,"A") -> 0
C33: ③GAP（②-①） | D33: =D32-D31 -> 0 | E33: =E32-E31 -> 0 | F33: =F32-F31 -> 0 | G33: =G32-G31 -> 0 | H33: =H32-H31 -> 0 | I33: =I32-I31 -> 0 | J33: =J32-J31 -> 0 | K33: =K32-K31 -> 0 | ... O33: =O32-O31 -> 0

Sheet 【表示用】9期売上
B3: ＜単月実績（千円）＞
D4: 9月 | E4: 10月 | F4: 11月 | G4: 12月 | H4: 1月 | I4: 2月 | J4: 3月 | K4: 4月 | L4: 5月 | M4: 6月 | N4: 7月 | O4: 8月 | P4: 合計
C5: ①目標 | D5: 21000 | E5: 28000 | F5: 28000 | G5: 28000 | H5: 24500 | I5: 28000 | J5: 35000 | K5: 31500 | L5: 31500 | M5: 35000 | N5: 31500 | O5: 28000 | P5: =SUM(D5:O5) -> 350000
B6: 成立＋A | C6: ②実績 | D6: =SUM(D33:D34) -> 21320 | E6: =SUM(E33:E34) -> 23961 | F6: =SUM(F33:F34) -> 21500 | G6: =SUM(G33:G34) -> 19182 | H6: =SUM(H33:H34) -> 14900 | I6: =SUM(I33:I34) -> 21100 | J6: =SUM(J33:J34) -> 17350 | K6: =SUM(K33:K34) -> 7650 | ... P6: =SUM(P33:P34) -> 167613
C7: ③GAP（②-①） | D7: =D6-D5 -> 320 | E7: =E6-E5 -> -4039 | F7: =F6-F5 -> -6500 | G7: =G6-G5 -> -8818 | H7: =H6-H5 -> -9600 | I7: =I6-I5 -> -6900 | J7: =J6-J5 -> -17650 | K7: =K6-K5 -> -23850 | ... P7: =P6-P5 -> -182387
B8: 確度換算 | C8: ④実績 | D8: =D41 -> 21320 | E8: =E41 -> 24961 | F8: =F41 -> 22500 | G8: =G41 -> 20182 | H8: =H41 -> 15300 | I8: =I41 -> 21900 | J8: =J41 -> 19940 | K8: =K41 -> 12192 | ... O8: =O41 -> 4512 | P8: =SUM(D8:O8) -> 196701
C9: ⑤GAP（④-①） | D9: =D8-D5 -> 320 | E9: =E8-E5 -> -3039 | F9: =F8-F5 -> -5500 | G9: =G8-G5 -> -7818 | H9: =H8-H5 -> -9200 | I9: =I8-I5 -> -6100 | J9: =J8-J5 -> -15060 | K9: =K8-K5 -> -19308 | ... P9: =P8-P5 -> -153299
B11: ＜累積実績（千円）＞
D12: 9月 | E12: 10月 | F12: 11月 | G12: 12月 | H12: 1月 | I12: 2月 | J12: 3月 | K12: 4月 | L12: 5月 | M12: 6月 | N12: 7月 | O12: 8月 | P12: 合計
C13: ①目標 | D13: 21000 | E13: =D13+E5 -> 49000 | F13: =E13+F5 -> 77000 | G13: =F13+G5 -> 105000 | H13: =G13+H5 -> 129500 | I13: =H13+I5 -> 157500 | J13: =I13+J5 -> 192500 | K13: =J13+K5 -> 224000 | L13: =K13+L5 -> 255500 | ... O13: =N13+O5 -> 350000 | P13: =O13 -> 350000
B14: 成立＋A | C14: ②実績 | D14: =D6 -> 21320 | E14: =D14+E6 -> 45281 | F14: =E14+F6 -> 66781 | G14: =F14+G6 -> 85963 | H14: =G14+H6 -> 100863 | I14: =H14+I6 -> 121963 | J14: =I14+J6 -> 139313 | K14: =J14+K6 -> 146963 | L14: =K14+L6 -> 154613 | ... O14: =N14+O6 -> 167613 | P14: =O14 -> 167613
C15: ③GAP（②-①） | D15: =D14-D13 -> 320 | E15: =E14-E13 -> -3719 | F15: =F14-F13 -> -10219 | G15: =G14-G13 -> -19037 | H15: =H14-H13 -> -28637 | I15: =I14-I13 -> -35537 | J15: =J14-J13 -> -53187 | K15: =K14-K13 -> -77037 | ... P15: =P14-P13 -> -182387
B16: 確度換算 | C16: ④実績 | D16: =D8 -> 21320 | E16: =D16+E8 -> 46281 | F16: =E16+F8 -> 68781 | G16: =F16+G8 -> 88963 | H16: =G16+H8 -> 104263 | I16: =H16+I8 -> 126163 | J16: =I16+J8 -> 146103 | K16: =J16+K8 -> 158295 | L16: =K16+L8 -> 171057 | ... O16: =N16+O8 -> 196701 | P16: =O16 -> 196701
C17: ⑤GAP（④-①） | D17: =D16-D13 -> 320 | E17: =E16-E13 -> -2719 | F17: =F16-F13 -> -8219 | G17: =G16-G13 -> -16037 | H17: =H16-H13 -> -25237 | I17: =I16-I13 -> -31337 | J17: =J16-J13 -> -46397 | K17: =K16-K13 -> -65705 | ... P17: =P16-P13 -> -153299
B19: ＜対前年度比較：成立＋A＞
D20: 9月 | E20: 10月 | F20: 11月 | G20: 12月 | H20: 1月 | I20: 2月 | J20: 3月 | K20: 4月 | L20: 5月 | M20: 6月 | N20: 7月 | O20: 8月 | P20: 合計
B21: 8期実績 | C21: ①8期売上（単月） | D21: 10170 | E21: 14160 | F21: 13560 | G21: 11410 | H21: 10620 | I21: 12510 | J21: 16400 | K21: 10630 | L21: 17050 | M21: 19150 | N21: 20310 | O21: 13530 | P21: =SUM(D21:O21) -> 169500
C22: ②8期売上（累積） | D22: =D21 -> 10170 | E22: =D22+E21 -> 24330 | F22: =E22+F21 -> 37890 | G22: =F22+G21 -> 49300 | H22: =G22+H21 -> 59920 | I22: =H22+I21 -> 72430 | J22: =I22+J21 -> 88830 | K22: =J22+K21 -> 99460 | L22: =K22+L21 -> 116510 | ... O22: =N22+O21 -> 169500 | P22: =O22 -> 169500
B23: 単月 | C23: ③9期実績 | D23: =D6 -> 21320 | E23: =E6 -> 23961 | F23: =F6 -> 21500 | G23: =G6 -> 19182 | H23: =H6 -> 14900 | I23: =I6 -> 21100 | J23: =J6 -> 17350 | K23: =K6 -> 7650 | ... P23: =P6 -> 167613
C24: ④GAP（③-①） | D24: =D23-D21 -> 11150 | E24: =E23-E21 -> 9801 | F24: =F23-F21 -> 7940 | G24: =G23-G21 -> 7772 | H24: =H23-H21 -> 4280 | I24: =I23-I21 -> 8590 | J24: =J23-J21 -> 950 | K24: =K23-K21 -> -2980 | ... P24: =P23-P21 -> -1887
B25: 累積 | C25: ⑤9期実績 | D25: =D14 -> 21320 | E25: =E14 -> 45281 | F25: =F14 -> 66781 | G25: =G14 -> 85963 | H25: =H14 -> 100863 | I25: =I14 -> 121963 | J25: =J14 -> 139313 | K25: =K14 -> 146963 | ... P25: =P14 -> 167613
C26: ⑥GAP（⑤-①） | D26: =D25-D22 -> 11150 | E26: =E25-E22 -> 20951 | F26: =F25-F22 -> 28891 | G26: =G25-G22 -> 36663 | H26: =H25-H22 -> 40943 | I26: =I25-I22 -> 49533 | J26: =J25-J22 -> 50483 | K26: =K25-K22 -> 47503 | ... P26: =P25-P22 -> -1887
B30: ＜確度別金額・単月（千円）＞※換算前
D31: 9月 | E31: 10月 | F31: 11月 | G31: 12月 | H31: 1月 | I31: 2月 | J31: 3月 | K31: 4月 | L31: 5月 | M31: 6月 | N31: 7月 | O31: 8月 | P31: 合計
C32: 合計 | D32: =SUM(D33:D37) -> 21320 | E32: =SUM(E33:E37) -> 27961 | F32: =SUM(F33:F37) -> 25500 | G32: =SUM(G33:G37) -> 23182 | H32: =SUM(H33:H37) -> 16900 | I32: =SUM(I33:I37) -> 25100 | J32: =SUM(J33:J37) -> 24550 | K32: =SUM(K33:K37) -> 23310 | ... O32: =SUM(O33:O37) -> 13360 | P32: =SUM(D32:O32) -> 269553
C33: 成立 | D33: =SUMIF('【入力用②】案件ごと売上（D案件以上）'!$G$5:$G$1048576,【表示用】9期売上!$C33,'【入力用②】案件ごと売上（D案件以上）'!N$5:N$1048576) -> 19320 | E33: =SUMIF('【入力用②】案件ごと売上（D案件以上）'!$G$5:$G$1048576,【表示用】9期売上!$C33,'【入力用②】案件ごと売上（D案件以上）'!O$5:O$1048576) -> 21961 | F33: =SUMIF('【入力用②】案件ごと売上（D案件以上）'!$G$5:$G$1048576,【表示用】9期売上!$C33,'【入力用②】案件ごと売上（D案件以上）'!P$5:P$1048576) -> 19500 | G33: =SUMIF('【入力用②】案件ごと売上（D案件以上）'!$G$5:$G$1048576,【表示用】9期売上!$C33,'【入力用②】案件ごと売上（D案件以上）'!Q$5:Q$1048576) -> 16182 | H33: =SUMIF('【入力用②】案件ごと売上（D案件以上）'!$G$5:$G$1048576,【表示用】9期売上!$C33,'【入力用②】案件ごと売上（D案件以上）'!R$5:R$1048576) -> 11700 | I33: =SUMIF('【入力用②】案件ごと売上（D案件以上）'!$G$5:$G$1048576,【表示用】9期売上!$C33,'【入力用②】案件ごと売上（D案件以上）'!S$5:S$1048576) -> 16200 | J33: =SUMIF('【入力用②】案件ごと売上（D案件以上）'!$G$5:$G$1048576,【表示用】9期売上!$C33,'【入力用②】案件ごと売上（D案件以上）'!T$5:T$1048576) -> 11150 | K33: =SUMIF('【入力用②】案件ごと売上（D案件以上）'!$G$5:$G$1048576,【表示用】9期売上!$C33,'【入力用②】案件ごと売上（D案件以上）'!U$5:U$1048576) -> 5450 | ... O33: =SUMIF('【入力用②】案件ごと売上（D案件以上）'!$G$5:$G$1048576,【表示用】9期売上!$C33,'【入力用②】案件ごと売上（D案件以上）'!Y$5:Y$1048576) -> 0 | P33: =SUM(D33:O33) -> 137813
C34: A | D34: =SUMIF('【入力用②】案件ごと売上（D案件以上）'!$G$5:$G$1048576,【表示用】9期売上!$C34,'【入力用②】案件ごと売上（D案件以上）'!N$5:N$1048576) -> 2000 | E34: =SUMIF('【入力用②】案件ごと売上（D案件以上）'!$G$5:$G$1048576,【表示用】9期売上!$C34,'【入力用②】案件ごと売上（D案件以上）'!O$5:O$1048576) -> 2000 | F34: =SUMIF('【入力用②】案件ごと売上（D案件以上）'!$G$5:$G$1048576,【表示用】9期売上!$C34,'【入力用②】案件ごと売上（D案件以上）'!P$5:P$1048576) -> 2000 | G34: =SUMIF('【入力用②】案件ごと売上（D案件以上）'!$G$5:$G$1048576,【表示用】9期売上!$C34,'【入力用②】案件ごと売上（D案件以上）'!Q$5:Q$1048576) -> 3000 | H34: =SUMIF('【入力用②】案件ごと売上（D案件以上）'!$G$5:$G$1048576,【表示用】9期売上!$C34,'【入力用②】案件ごと売上（D案件以上）'!R$5:R$1048576) -> 3200 | I34: =SUMIF('【入力用②】案件ごと売上（D案件以上）'!$G$5:$G$1048576,【表示用】9期売上!$C34,'【入力用②】案件ごと売上（D案件以上）'!S$5:S$1048576) -> 4900 | J34: =SUMIF('【入力用②】案件ごと売上（D案件以上）'!$G$5:$G$1048576,【表示用】9期売上!$C34,'【入力用②】案件ごと売上（D案件以上）'!T$5:T$1048576) -> 6200 | K34: =SUMIF('【入力用②】案件ごと売上（D案件以上）'!$G$5:$G$1048576,【表示用】9期売上!$C34,'【入力用②】案件ごと売上（D案件以上）'!U$5:U$1048576) -> 2200 | ... O34: =SUMIF('【入力用②】案件ごと売上（D案件以上）'!$G$5:$G$1048576,【表示用】9期売上!$C34,'【入力用②】案件ごと売上（D案件以上）'!Y$5:Y$1048576) -> 700 | P34: =SUM(D34:O34) -> 29800
C35: B | D35: =SUMIF('【入力用②】案件ごと売上（D案件以上）'!$G$5:$G$1048576,【表示用】9期売上!$C35,'【入力用②】案件ごと売上（D案件以上）'!N$5:N$1048576) -> 0 | E35: =SUMIF('【入力用②】案件ごと売上（D案件以上）'!$G$5:$G$1048576,【表示用】9期売上!$C35,'【入力用②】案件ごと売上（D案件以上）'!O$5:O$1048576) -> 0 | F35: =SUMIF('【入力用②】案件ごと売上（D案件以上）'!$G$5:$G$1048576,【表示用】9期売上!$C35,'【入力用②】案件ごと売上（D案件以上）'!P$5:P$1048576) -> 0 | G35: =SUMIF('【入力用②】案件ごと売上（D案件以上）'!$G$5:$G$1048576,【表示用】9期売上!$C35,'【入力用②】案件ごと売上（D案件以上）'!Q$5:Q$1048576) -> 0 | H35: =SUMIF('【入力用②】案件ごと売上（D案件以上）'!$G$5:$G$1048576,【表示用】9期売上!$C35,'【入力用②】案件ごと売上（D案件以上）'!R$5:R$1048576) -> 0 | I35: =SUMIF('【入力用②】案件ごと売上（D案件以上）'!$G$5:$G$1048576,【表示用】9期売上!$C35,'【入力用②】案件ごと売上（D案件以上）'!S$5:S$1048576) -> 0 | J35: =SUMIF('【入力用②】案件ごと売上（D案件以上）'!$G$5:$G$1048576,【表示用】9期売上!$C35,'【入力用②】案件ごと売上（D案件以上）'!T$5:T$1048576) -> 2000 | K35: =SUMIF('【入力用②】案件ごと売上（D案件以上）'!$G$5:$G$1048576,【表示用】9期売上!$C35,'【入力用②】案件ごと売上（D案件以上）'!U$5:U$1048576) -> 2160 | ... O35: =SUMIF('【入力用②】案件ごと売上（D案件以上）'!$G$5:$G$1048576,【表示用】9期売上!$C35,'【入力用②】案件ごと売上（D案件以上）'!Y$5:Y$1048576) -> 2160 | P35: =SUM(D35:O35) -> 12840
C36: C | D36: =SUMIF('【入力用②】案件ごと売上（D案件以上）'!$G$5:$G$1048576,【表示用】9期売上!$C36,'【入力用②】案件ごと売上（D案件以上）'!N$5:N$1048576) -> 0 | E36: =SUMIF('【入力用②】案件ごと売上（D案件以上）'!$G$5:$G$1048576,【表示用】9期売上!$C36,'【入力用②】案件ごと売上（D案件以上）'!O$5:O$1048576) -> 2000 | F36: =SUMIF('【入力用②】案件ごと売上（D案件以上）'!$G$5:$G$1048576,【表示用】9期売上!$C36,'【入力用②】案件ごと売上（D案件以上）'!P$5:P$1048576) -> 2000 | G36: =SUMIF('【入力用②】案件ごと売上（D案件以上）'!$G$5:$G$1048576,【表示用】9期売上!$C36,'【入力用②】案件ごと売上（D案件以上）'!Q$5:Q$1048576) -> 2000 | H36: =SUMIF('【入力用②】案件ごと売上（D案件以上）'!$G$5:$G$1048576,【表示用】9期売上!$C36,'【入力用②】案件ごと売上（D案件以上）'!R$5:R$1048576) -> 0 | I36: =SUMIF('【入力用②】案件ごと売上（D案件以上）'!$G$5:$G$1048576,【表示用】9期売上!$C36,'【入力用②】案件ごと売上（D案件以上）'!S$5:S$1048576) -> 0 | J36: =SUMIF('【入力用②】案件ごと売上（D案件以上）'!$G$5:$G$1048576,【表示用】9期売上!$C36,'【入力用②】案件ごと売上（D案件以上）'!T$5:T$1048576) -> 1500 | K36: =SUMIF('【入力用②】案件ごと売上（D案件以上）'!$G$5:$G$1048576,【表示用】9期売上!$C36,'【入力用②】案件ごと売上（D案件以上）'!U$5:U$1048576) -> 3300 | ... O36: =SUMIF('【入力用②】案件ごと売上（D案件以上）'!$G$5:$G$1048576,【表示用】9期売上!$C36,'【入力用②】案件ごと売上（D案件以上）'!Y$5:Y$1048576) -> 2000 | P36: =SUM(D36:O36) -> 22800
C37: D | D37: =SUMIF('【入力用②】案件ごと売上（D案件以上）'!$G$5:$G$1048576,【表示用】9期売上!$C37,'【入力用②】案件ごと売上（D案件以上）'!N$5:N$1048576) -> 0 | E37: =SUMIF('【入力用②】案件ごと売上（D案件以上）'!$G$5:$G$1048576,【表示用】9期売上!$C37,'【入力用②】案件ごと売上（D案件以上）'!O$5:O$1048576) -> 2000 | F37: =SUMIF('【入力用②】案件ごと売上（D案件以上）'!$G$5:$G$1048576,【表示用】9期売上!$C37,'【入力用②】案件ごと売上（D案件以上）'!P$5:P$1048576) -> 2000 | G37: =SUMIF('【入力用②】案件ごと売上（D案件以上）'!$G$5:$G$1048576,【表示用】9期売上!$C37,'【入力用②】案件ごと売上（D案件以上）'!Q$5:Q$1048576) -> 2000 | H37: =SUMIF('【入力用②】案件ごと売上（D案件以上）'!$G$5:$G$1048576,【表示用】9期売上!$C37,'【入力用②】案件ごと売上（D案件以上）'!R$5:R$1048576) -> 2000 | I37: =SUMIF('【入力用②】案件ごと売上（D案件以上）'!$G$5:$G$1048576,【表示用】9期売上!$C37,'【入力用②】案件ごと売上（D案件以上）'!S$5:S$1048576) -> 4000 | J37: =SUMIF('【入力用②】案件ごと売上（D案件以上）'!$G$5:$G$1048576,【表示用】9期売上!$C37,'【入力用②】案件ごと売上（D案件以上）'!T$5:T$1048576) -> 3700 | K37: =SUMIF('【入力用②】案件ごと売上（D案件以上）'!$G$5:$G$1048576,【表示用】9期売上!$C37,'【入力用②】案件ごと売上（D案件以上）'!U$5:U$1048576) -> 10200 | ... O37: =SUMIF('【入力用②】案件ごと売上（D案件以上）'!$G$5:$G$1048576,【表示用】9期売上!$C37,'【入力用②】案件ごと売上（D案件以上）'!Y$5:Y$1048576) -> 8500 | P37: =SUM(D37:O37) -> 66300
B39: ＜確度別金額・単月（千円）＞※換算後
D40: 9月 | E40: 10月 | F40: 11月 | G40: 12月 | H40: 1月 | I40: 2月 | J40: 3月 | K40: 4月 | L40: 5月 | M40: 6月 | N40: 7月 | O40: 8月 | P40: 合計
C41: 合計 | D41: =SUM(D42:D46) -> 21320 | E41: =SUM(E42:E46) -> 24961 | F41: =SUM(F42:F46) -> 22500 | G41: =SUM(G42:G46) -> 20182 | H41: =SUM(H42:H46) -> 15300 | I41: =SUM(I42:I46) -> 21900 | J41: =SUM(J42:J46) -> 19940 | K41: =SUM(K42:K46) -> 12192 | ... O41: =SUM(O42:O46) -> 4512 | P41: =SUM(D41:O41) -> 196701
B42: 1 | C42: 成立 | D42: =D33*$B42 -> 19320 | E42: =E33*$B42 -> 21961 | F42: =F33*$B42 -> 19500 | G42: =G33*$B42 -> 16182 | H42: =H33*$B42 -> 11700 | I42: =I33*$B42 -> 16200 | J42: =J33*$B42 -> 11150 | K42: =K33*$B42 -> 5450 | ... O42: =O33*$B42 -> 0 | P42: =SUM(D42:O42) -> 137813
B43: 1 | C43: A | D43: =D34*$B43 -> 2000 | E43: =E34*$B43 -> 2000 | F43: =F34*$B43 -> 2000 | G43: =G34*$B43 -> 3000 | H43: =H34*$B43 -> 3200 | I43: =I34*$B43 -> 4900 | J43: =J34*$B43 -> 6200 | K43: =K34*$B43 -> 2200 | ... O43: =O34*$B43 -> 700 | P43: =SUM(D43:O43) -> 29800
B44: 0.7 | C44: B | D44: =D35*$B44 -> 0 | E44: =E35*$B44 -> 0 | F44: =F35*$B44 -> 0 | G44: =G35*$B44 -> 0 | H44: =H35*$B44 -> 0 | I44: =I35*$B44 -> 0 | J44: =J35*$B44 -> 1400 | K44: =K35*$B44 -> 1512 | ... O44: =O35*$B44 -> 1512 | P44: =SUM(D44:O44) -> 8988
B45: 0.3 | C45: C | D45: =D36*$B45 -> 0 | E45: =E36*$B45 -> 600 | F45: =F36*$B45 -> 600 | G45: =G36*$B45 -> 600 | H45: =H36*$B45 -> 0 | I45: =I36*$B45 -> 0 | J45: =J36*$B45 -> 450 | K45: =K36*$B45 -> 990 | ... O45: =O36*$B45 -> 600 | P45: =SUM(D45:O45) -> 6840
B46: 0.2 | C46: D | D46: =D37*$B46 -> 0 | E46: =E37*$B46 -> 400 | F46: =F37*$B46 -> 400 | G46: =G37*$B46 -> 400 | H46: =H37*$B46 -> 400 | I46: =I37*$B46 -> 800 | J46: =J37*$B46 -> 740 | K46: =K37*$B46 -> 2040 | ... O46: =O37*$B46 -> 1700 | P46: =SUM(D46:O46) -> 13260

Sheet 【表示用】案件ごと売上
A1: 確度 | B1: (複数のアイテム)
A3: 行ラベル | B3: 合計 / 9期分 | C3: 合計 / 9月 | D3: 合計 / 10月 | E3: 合計 / 11月 | F3: 合計 / 12月 | G3: 合計 / 1月 | H3: 合計 / 2月 | I3: 合計 / 3月 | J3: 合計 / 4月 | K3: 合計 / 5月 | L3: 合計 / 6月 | M3: 合計 / 7月 | N3: 合計 / 8月
A4: 01_伊藤ハム米久ホールディングス_エンゲージメント向上PJT | B4: 550 | C4: 550
A5: 02_パラドックス_森の歩き方実装支援 | B5: 300 | C5: 300
A6: 03_日本総研_キャリア入社者課題分析 | B6: 600 | C6: 600
A7: 05_YAMAGATA_新事業立ち上げ支援 | B7: 14500 | C7: 3700 | D7: 3600 | E7: 3600 | F7: 3600
A8: 07_豊田通商_メタルプラス | B8: 6750 | D8: 2250 | E8: 2250 | F8: 2250
A9: 08_OKI_人材面を主とした組織診断 | B9: 4000 | C9: 2000 | D9: 2000
A10: 09_宮﨑製鋼_エンゲージメントサーベイ | B10: 500 | C10: 140 | D10: 360
A11: 10_オムロンエキスパートエンジニアリング_データ分析 | B11: 2000 | D11: 500 | E11: 500 | F11: 1000
A12: 11_MSプライマリー_エンゲージメントサーベイ | B12: 7000 | C12: 2000 | D12: 1500 | E12: 1500 | F12: 2000
A13: 12_アートプレスト_2025年上期人事施策実行支援 | B13: 6700 | C13: 6700
A14: 13_アートプレスト_2025年下期人事施策実行支援 | B14: 37900 | D14: 8000 | E14: 7800 | F14: 5900 | G14: 6100 | H14: 5800 | I14: 4300
A15: 14_アートプレスト_経営層候補者向け研修実行支援 | B15: 250 | E15: 250
A16: 15_アートプレスト_役員研修 | B16: 100 | D16: 100
A17: 16_JALUX_ビジネス変革Community | B17: 750 | D17: 750
A18: 17_JALUX_業務効率化 | B18: 2300 | C18: 480 | D18: 440
A19: 18_パラマウントベッド_管理職WS＆部門幹部ディスカッション | B19: 4470 | D19: 1881 | F19: 800
A20: 19_asics_HRBP支援 | B20: 400 | C20: 400
A21: 20_コメダ_FC対応力向上 | B21: 2000 | C21: 600 | D21: 600 | E21: 800
A22: 21_ローソンエンタテインメント_人事制度・育成概要設計 | B22: 12300 | C22: 2050 | D22: 2050 | E22: 2050 | F22: 2050 | G22: 2050 | H22: 2050
A23: 22_オーネスト_MVV浸透支援Phase3 | B23: 1300 | C23: 1300
A24: 25_パラマウントベッド_女性社員交流会 企画支援 | B24: 500 | C24: 500
A25: 29_パラマウントベッド_女性社員交流会 キックオフイベント支援 | B25: 700 | D25: 280
A26: 30_パラマウントベッド_女性社員交流会_女性キャリア研修 | B26: 1246 | E26: 117 | F26: 132
A27: 31_パーソルクロステクノロジー_社内広報業務支援 | B27: 2250
A28: 33_田島ルーフィング_推せる職場診断 | B28: 3100 | D28: 1000 | E28: 1000 | F28: 300 | G28: 300 | H28: 500
A29: 36_パラドックス_森の歩き方実装支援（10月以降） | B29: 1650 | D29: 150 | E29: 300 | F29: 300 | G29: 300 | H29: 300 | I29: 300
A30: 40_三井情報_人材マネジメントアドバイザリー | B30: 3500 | E30: 700 | F30: 700 | G30: 700 | H30: 700 | I30: 700
A31: 総計 | B31: 117616 | C31: 21320 | D31: 25461 | E31: 20867 | F31: 19032 | G31: 9450 | H31: 9350 | I31: 5300

Sheet 【入力用①】パイプライン
B2: No | C2: クライアント | D2: 案件 | E2: テーマ（分類） | F2: 流入ルート | G2: 金額（万円） | H2: 期間（月） | I2: 期間補足 | J2: 営業担当 | K2: 確度 | L2: 与信新規申請 | M2: 与信限度額 超過申請 | N2: MM/DD | O2: 攻略作戦 | P2: 45958 | Q2: 45944 | R2: 45937 | S2: 45902 | T2: 45895
B3: =ROW(A3)-2 -> 1 | C3: JFEエンジニアリング | D3: タレマネ活用 | E3: ⑥人材育成コンサル | F3: HRPトスアップ | J3: 弓本、小川 | S3: タレマネツールの導入について、先方DX推進室で候補選定中。別途人事担当者様にアプローチ予定。 | U3: e
B4: =ROW(A4)-2 -> 2 | C4: PHCホールディングス | D4: オンボーディング環境整備 | E4: ②採用・オンボーディング | F4: HRPトスアップ | J4: 弓本、小川 | O4: 担当部長を起点に人事担当役員にアプローチ 当面は若手社員の流出防止目的のキャリア研修で信頼関係構築。２年後採用倍増計画に合わせ受け入れ態勢整備の案件を提案（来年４月以降プロジェクト） | S4: 先方担当（横山様）と小川さんで会話済み。コンサル側はすぐの受注ではなさそう。 | U4: e
B5: =ROW(A5)-2 -> 3 | C5: テプコ・ソリューション・アドバンス | D5: MVV浸透 | E5: ⑦その他 | F5: HRPトスアップ（新） | J5: 小川 | U5: e
B6: =ROW(A6)-2 -> 4 | C6: ユニリタ | U6: e
B7: =ROW(A7)-2 -> 5 | C7: コメダ | D7: 大学充実化 | E7: ⑥人材育成コンサル | F7: HRPトスアップ | J7: 森田、小川 | O7: 人事担当役員向けに大学のタレマネ機能拡充の提案 館越経由 | U7: e
B8: =ROW(A8)-2 -> 6 | C8: ENEOS | D8: マネジメント層強化 | E8: ⑥人材育成コンサル | F8: HRPトスアップ | J8: 小川 | O8: 部長研修の延長線上で、管理職のマネジメント力強化につながる施策として推せる職場づくりを人事担当役員に提案 | U8: e
B9: =ROW(A9)-2 -> 7 | C9: デジタルガレージ | D9: 人的資本経営 | E9: ⑥人材育成コンサル | F9: HP、セミナー経由 | J9: 小川 | U9: e
B10: =ROW(A10)-2 -> 8 | C10: メイテック | U10: e
B11: =ROW(A11)-2 -> 9 | C11: 帝人 | U11: e
B12: =ROW(A12)-2 -> 10 | C12: BeeX | D12: キャリアパス設計 | F12: EXPO | G12: 450～600万円 | H12: 3 | J12: 小川・啓亮 | K12: D | S12: 他社の事業戦略～人材ポートフォリオの調査及び自社の人材像とあるべき人材ポートフォリオの検討に興味を持っている。先方人事部長のほうで方向性を整理し、再度スコープをすり合わせる打ち合わせを打診する | T12: 8/29先方人事部長・マネージャーと打ち合わせ予定 | U12: e
B13: =ROW(A13)-2 -> 11 | C13: 千葉県 | D13: サーベイ活用 | F13: EXPO | J13: 啓亮、小川 | U13: e
B14: =ROW(A14)-2 -> 12 | C14: イオン | U14: e
B15: =ROW(A15)-2 -> 13 | C15: 安部日鋼工業 | D15: 経営WS | F15: HRPトスアップ（新） | J15: 啓亮、小川 | U15: e
B16: =ROW(A16)-2 -> 14 | C16: SUBARU | D16: タレマネ | J16: 小川 | U16: e
B17: =ROW(A17)-2 -> 15 | C17: 安田工業 | D17: 推せる職場づくり | E17: ①推せる職場づくり | F17: HRPトスアップ（新） | J17: 弓本、小川 | O17: エンゲージメント向上にむけた３か年計画を伴走支援 人事部長⇒社長の説得を支援 | S17: 先方とは2回接点を持っており、先方希望の資料を提供済み。池本くんで状況確認中。 | U17: e
B18: =ROW(A18)-2 -> 16 | C18: 西武HD | D18: オンボーディング | E18: ②採用・オンボーディング | J18: 弓本 | K18: C | U18: e
B19: =ROW(A19)-2 -> 17 | C19: キューピー | U19: e
B20: =ROW(A20)-2 -> 18 | C20: サラヤ | U20: e
B21: =ROW(A21)-2 -> 19 | C21: 昭和産業 | D21: MVV浸透 | E21: ⑦その他 | F21: HRPトスアップ（新） | J21: 小川 | U21: e
B22: =ROW(A22)-2 -> 20 | C22: 三菱UFJニコス | D22: 育成方針策定 | E22: ⑥人材育成コンサル | F22: HRPトスアップ | J22: 啓亮、小川 | U22: e
B23: =ROW(A23)-2 -> 21 | C23: アサヒクオリティアンドイノベーションズ | D23: スキルマップ | E23: ⑥人材育成コンサル | F23: WHI経由 | J23: 啓亮、小川 | U23: e
B24: =ROW(A24)-2 -> 22 | C24: オーネスト | D24: 評価制度設計 | E24: ⑤人事制度改革 | F24: クロス | J24: 小川 | U24: e
B25: =ROW(A25)-2 -> 23 | C25: クレオテック | D25: キャリア形成支援 | E25: ⑥人材育成コンサル | F25: HRPトスアップ | J25: 小川 | U25: e
B26: =ROW(A26)-2 -> 24 | C26: インテージテクノスフィア | F26: HP、セミナー経由 | J26: 弓本、小川 | S26: 感謝会に参加後、PANAIサーベイのトライアルと先方から懇親会希望の連絡あり。 | U26: e
B27: =ROW(A27)-2 -> 25 | C27: 兼松 | D27: 育成体系整備 | E27: ⑥人材育成コンサル | J27: 小川 | U27: e
B28: =ROW(A28)-2 -> 26 | C28: オムロンエキスパートエンジニアリング | D28: エンゲージメントサーベイ | F28: カオナビ | G28: 100～250万 | H28: 3 | I28: 202510～12末 | J28: 芹澤 | T28: 提案書・追加資料提出済み。当社でほぼ確定のご連絡を頂いた。 | U28: e
B29: =ROW(A29)-2 -> 27 | C29: 北九州市役所 | F29: HRPトスアップ | G29: 200万円 | H29: 2 | J29: 啓亮 | P29: サーベイ分析＆動画・ガイド作成＆研修設計・実施で400万円（4か月）。提案・契約工数と金額が見合わないため辞退 | Q29: 10月中旬に公告予定 | R29: 10月中旬に公告予定 | S29: エンゲージメントサーベイの簡易分析と説明用動画作成で200万円程度。入札参加資格獲得の工数や公共提案の工数を踏まえた際に、やるべきかどうか相談 | U29: e
B30: =ROW(A30)-2 -> 28 | C30: 社会医療法人友愛会 | U30: e
B31: =ROW(A31)-2 -> 29 | C31: 水戸済生会総合病院 | U31: e
B32: =ROW(A32)-2 -> 30 | C32: 日本毛織 | U32: e
B33: =ROW(A33)-2 -> 31 | C33: 人事院 | D33: キャリア形成支援、オンボーディング | E33: ⑥人材育成コンサル | F33: HP、セミナー経由 | G33: 250万円 ※来年度 | J33: 小川 | U33: e
B34: =ROW(A34)-2 -> 32 | C34: 東京消防庁 | D34: 育成体系整備 | E34: ⑥人材育成コンサル | F34: HP、セミナー経由 | J34: 小川 | U34: e
B35: =ROW(A35)-2 -> 33 | C35: アイシン | D35: 育成体系整備 | E35: ⑥人材育成コンサル | F35: HRPトスアップ | J35: 森田 | U35: e
B36: =ROW(A36)-2 -> 34 | C36: アントステラ | D36: 人材戦略アドバイザリー | E36: ⑤人事制度改革 | F36: HRPトスアップ | J36: 小川 | U36: e
B37: =ROW(A37)-2 -> 35 | C37: ひらまつ | D37: キャリアパス＆育成体系 | F37: 紹介（パラドックス） | G37: 1200万円 | H37: 6 | I37: 10月～3月 | J37: 小川・啓亮 | P37: パラドックス高田さんとCOOの方で11月までにスコープを定めるとのこと。スタートするとしても12月以降となりそう。 | Q37: 今週中に連絡なければ、来週頭に一度連絡 | R37: パラドックス担当→COOへ提案書展開。ひきつづきパラドックス担当と連携して進める | S37: 8/29パラドックスと提案内容すり合わせMTG→9/5先方現地訪問予定 | T37: 8/29パラドックスと提案内容すり合わせMTG→9/5先方現地訪問予定 | U37: e
B38: =ROW(A38)-2 -> 36 | C38: アールビーコントロールズ | F38: HRPトスアップ（新） | J38: 小川 | U38: e
B39: =ROW(A39)-2 -> 37 | C39: アルプスアルパイン | F39: HRPトスアップ（新） | J39: 小川
B40: =ROW(A40)-2 -> 38 | C40: デンソーソリューション | F40: HRPトスアップ | J40: 小川
B41: =ROW(A41)-2 -> 39 | C41: ブラザー工業 | D41: サーベイ活用 | J41: 小川
...

Sheet 【入力用②】案件ごと売上（D案件以上）
A1: ※黄色セルは手動入力、行挿入はNG（案件Noが変わってしまうため）
I3: =SUM(I5:I44) -> 178654 | J3: ※計算用 | N3: ◆月別売上
A4: 継続 | B4: 案件No | C4: クライアント名 | D4: 案件名 | E4: PIVOT用_PJ管理 | F4: 案件種類 | G4: 確度 | H4: PIC | I4: 9期分 PJ全体売上 （千円） | J4: 月別売上合計 （千円） | K4: 差額 | L4: 期間 (月) | M4: 月単価 (千円) | N4: 9月 | O4: 10月 | P4: 11月 | Q4: 12月 | R4: 1月 | S4: 2月 | T4: 3月 | U4: 4月 | V4: 5月 | W4: 6月 | X4: 7月 | Y4: 8月 | Z4: *
B5: =ROW(A5)-4 -> 1 | C5: 伊藤ハム米久ホールディングス | D5: エンゲージメント向上PJT | E5: ="0"&B5&"_"&C5&"_"&D5 -> 01_伊藤ハム米久ホールディングス_エンゲージメント向上PJT | F5: 組織開発 | G5: 成立 | H5: 啓亮 | I5: 550 | J5: =SUM(N5:Y5) -> 550 | K5: =I5-J5 -> 0 | L5: 1 | M5: =IFERROR(I5/L5,"-") -> 550 | N5: 550 | Z5: *
B6: =ROW(A6)-4 -> 2 | C6: パラドックス | D6: 森の歩き方実装支援 | E6: ="0"&B6&"_"&C6&"_"&D6 -> 02_パラドックス_森の歩き方実装支援 | F6: 人材育成 | G6: 成立 | H6: 啓亮 | I6: 300 | J6: =SUM(N6:Y6) -> 300 | K6: =I6-J6 -> 0 | L6: 1 | M6: =IFERROR(I6/L6,"-") -> 300 | N6: 300 | Z6: *
B7: =ROW(A7)-4 -> 3 | C7: 日本総研 | D7: キャリア入社者課題分析 | E7: ="0"&B7&"_"&C7&"_"&D7 -> 03_日本総研_キャリア入社者課題分析 | F7: 人材育成 | G7: 成立 | H7: 啓亮 | I7: 600 | J7: =SUM(N7:Y7) -> 600 | K7: =I7-J7 -> 0 | L7: 1 | M7: =IFERROR(I7/L7,"-") -> 600 | N7: 600 | Z7: *
B8: =ROW(A8)-4 -> 4 | C8: 田島ルーフィング | D8: 推せる職場診断 | E8: ="0"&B8&"_"&C8&"_"&D8 -> 04_田島ルーフィング_推せる職場診断 | F8: 組織開発 | G8: D | H8: 啓亮 | J8: =SUM(N8:Y8) -> 0 | K8: =I8-J8 -> 0 | M8: =IFERROR(I8/L8,"-") -> - | Z8: *
B9: =ROW(A9)-4 -> 5 | C9: YAMAGATA | D9: 新事業立ち上げ支援 | E9: ="0"&B9&"_"&C9&"_"&D9 -> 05_YAMAGATA_新事業立ち上げ支援 | F9: その他 | G9: 成立 | H9: 丸田 | I9: 14500 | J9: =SUM(N9:Y9) -> 14500 | K9: =I9-J9 -> 0 | L9: 4 | M9: =IFERROR(I9/L9,"-") -> 3625 | N9: 3700 | O9: 3600 | P9: 3600 | Q9: 3600 | Z9: *
B10: =ROW(A10)-4 -> 6 | C10: 豊田通商 | D10: 人事KPI | E10: ="0"&B10&"_"&C10&"_"&D10 -> 06_豊田通商_人事KPI | F10: その他 | G10: 失注 | H10: 波多野 | I10: 6000 | J10: =SUM(N10:Y10) -> 6000 | K10: =I10-J10 -> 0 | L10: 3 | M10: =IFERROR(I10/L10,"-") -> 2000 | N10: 2000 | O10: 2000 | P10: 2000 | Z10: *
B11: =ROW(A11)-4 -> 7 | C11: 豊田通商 | D11: メタルプラス | E11: ="0"&B11&"_"&C11&"_"&D11 -> 07_豊田通商_メタルプラス | F11: その他 | G11: 成立 | H11: 波多野 | I11: 6750 | J11: =SUM(N11:Y11) -> 6750 | K11: =I11-J11 -> 0 | L11: 3 | M11: =IFERROR(I11/L11,"-") -> 2250 | P11: 2250 | Q11: 2250 | R11: 2250 | Z11: *
B12: =ROW(A12)-4 -> 8 | C12: OKI | D12: 人材面を主とした組織診断 | E12: ="0"&B12&"_"&C12&"_"&D12 -> 08_OKI_人材面を主とした組織診断 | F12: その他 | G12: 成立 | H12: 芹澤 | I12: 4000 | J12: =SUM(N12:Y12) -> 4000 | K12: =I12-J12 -> 0 | L12: 3.5 | M12: =IFERROR(I12/L12,"-") -> 1142.8571 | N12: 2000 | O12: 2000 | Z12: *
B13: =ROW(A13)-4 -> 9 | C13: 宮﨑製鋼 | D13: エンゲージメントサーベイ | E13: ="0"&B13&"_"&C13&"_"&D13 -> 09_宮﨑製鋼_エンゲージメントサーベイ | F13: その他 | G13: 成立 | H13: 芹澤 | I13: 500 | J13: =SUM(N13:Y13) -> 500 | K13: =I13-J13 -> 0 | L13: 3 | M13: =IFERROR(I13/L13,"-") -> 166.66667 | N13: 140 | O13: 360 | Z13: *
B14: =ROW(A14)-4 -> 10 | C14: オムロンエキスパートエンジニアリング | D14: データ分析 | E14: =B14&"_"&C14&"_"&D14 -> 10_オムロンエキスパートエンジニアリング_データ分析 | F14: その他 | G14: A | H14: 芹澤 | I14: 2000 | J14: =SUM(N14:Y14) -> 2000 | K14: =I14-J14 -> 0 | L14: 3 | M14: =IFERROR(I14/L14,"-") -> 666.66667 | O14: 500 | P14: 500 | Q14: 1000 | Z14: *
B15: =ROW(A15)-4 -> 11 | C15: MSプライマリー | D15: エンゲージメントサーベイ | E15: =B15&"_"&C15&"_"&D15 -> 11_MSプライマリー_エンゲージメントサーベイ | F15: その他 | G15: A | H15: 芹澤 | I15: 7000 | J15: =SUM(N15:Y15) -> 7000 | K15: =I15-J15 -> 0 | L15: 4 | M15: =IFERROR(I15/L15,"-") -> 1750 | N15: 2000 | O15: 1500 | P15: 1500 | Q15: 2000 | Z15: *
B16: =ROW(A16)-4 -> 12 | C16: アートプレスト | D16: 2025年上期人事施策実行支援 | E16: =B16&"_"&C16&"_"&D16 -> 12_アートプレスト_2025年上期人事施策実行支援 | F16: その他 | G16: 成立 | H16: 友祐 | I16: 6700 | J16: =SUM(N16:Y16) -> 6700 | K16: =I16-J16 -> 0 | L16: 1 | M16: =IFERROR(I16/L16,"-") -> 6700 | N16: 6700 | Z16: *
B17: =ROW(A17)-4 -> 13 | C17: アートプレスト | D17: 2025年下期人事施策実行支援 | E17: =B17&"_"&C17&"_"&D17 -> 13_アートプレスト_2025年下期人事施策実行支援 | F17: その他 | G17: 成立 | H17: 友祐 | I17: 37900 | J17: =SUM(N17:Y17) -> 37900 | K17: =I17-J17 -> 0 | L17: 6 | M17: =IFERROR(I17/L17,"-") -> 6316.6667 | O17: 8000 | P17: 7800 | Q17: 5100 | R17: 6100 | S17: 6200 | T17: 4700 | Z17: *
B18: =ROW(A18)-4 -> 14 | C18: アートプレスト | D18: 経営層候補者向け研修実行支援 | E18: =B18&"_"&C18&"_"&D18 -> 14_アートプレスト_経営層候補者向け研修実行支援 | F18: 人材育成 | G18: 成立 | H18: 友祐 | I18: 250 | J18: =SUM(N18:Y18) -> 250 | K18: =I18-J18 -> 0 | L18: 1 | M18: =IFERROR(I18/L18,"-") -> 250 | P18: 250 | Z18: *
B19: =ROW(A19)-4 -> 15 | C19: アートプレスト | D19: 役員研修 | E19: =B19&"_"&C19&"_"&D19 -> 15_アートプレスト_役員研修 | F19: 人材育成 | G19: 成立 | H19: 友祐 | I19: 100 | J19: =SUM(N19:Y19) -> 100 | K19: =I19-J19 -> 0 | L19: 1 | M19: =IFERROR(I19/L19,"-") -> 100 | O19: 100 | Z19: *
B20: =ROW(A20)-4 -> 16 | C20: JALUX | D20: ビジネス変革Community | E20: =B20&"_"&C20&"_"&D20 -> 16_JALUX_ビジネス変革Community | F20: その他 | G20: 成立 | H20: 森田 | I20: 750 | J20: =SUM(N20:Y20) -> 750 | K20: =I20-J20 -> 0 | L20: 1 | M20: =IFERROR(I20/L20,"-") -> 750 | O20: 750 | Z20: *
B21: =ROW(A21)-4 -> 17 | C21: JALUX | D21: 業務効率化 | E21: =B21&"_"&C21&"_"&D21 -> 17_JALUX_業務効率化 | F21: その他 | G21: 成立 | H21: 森田 | I21: 920 | J21: =SUM(N21:Y21) -> 920 | K21: =I21-J21 -> 0 | L21: 2 | M21: =IFERROR(I21/L21,"-") -> 460 | N21: 480 | O21: 440 | Z21: *
B22: =ROW(A22)-4 -> 18 | C22: パラマウントベッド | D22: 管理職WS＆部門幹部ディスカッション | E22: =B22&"_"&C22&"_"&D22 -> 18_パラマウントベッド_管理職WS＆部門幹部ディスカッション | F22: その他 | G22: 成立 | H22: 丸田 | I22: 4470 | J22: =SUM(N22:Y22) -> 2681 | K22: =I22-J22 -> 1789 | L22: 4 | M22: =IFERROR(I22/L22,"-") -> 1117.5 | O22: 1881 | Q22: 800 | Z22: *
B23: =ROW(A23)-4 -> 19 | C23: asics | D23: HRBP支援 | E23: =B23&"_"&C23&"_"&D23 -> 19_asics_HRBP支援 | F23: 組織開発 | G23: 成立 | H23: 森田 | I23: 400 | J23: =SUM(N23:Y23) -> 400 | K23: =I23-J23 -> 0 | L23: 1 | M23: =IFERROR(I23/L23,"-") -> 400 | N23: 400 | Z23: *
B24: =ROW(A24)-4 -> 20 | C24: コメダ | D24: FC対応力向上 | E24: =B24&"_"&C24&"_"&D24 -> 20_コメダ_FC対応力向上 | F24: 人材育成 | G24: 成立 | H24: 森田 | I24: 2000 | J24: =SUM(N24:Y24) -> 2000 | K24: =I24-J24 -> 0 | L24: 3 | M24: =IFERROR(I24/L24,"-") -> 666.66667 | N24: 600 | O24: 600 | P24: 800 | Z24: *
B25: =ROW(A25)-4 -> 21 | C25: ローソンエンタテインメント | D25: 人事制度・育成概要設計 | E25: =B25&"_"&C25&"_"&D25 -> 21_ローソンエンタテインメント_人事制度・育成概要設計 | F25: その他 | G25: 成立 | H25: 小川 | I25: 12300 | J25: =SUM(N25:Y25) -> 12300 | K25: =I25-J25 -> 0 | L25: 6 | M25: =IFERROR(I25/L25,"-") -> 2050 | N25: 2050 | O25: 2050 | P25: 2050 | Q25: 2050 | R25: 2050 | S25: 2050 | Z25: *
B26: =ROW(A26)-4 -> 22 | C26: オーネスト | D26: MVV浸透支援Phase3 | E26: =B26&"_"&C26&"_"&D26 -> 22_オーネスト_MVV浸透支援Phase3 | F26: 組織開発 | G26: 成立 | H26: 森田 | I26: 1300 | J26: =SUM(N26:Y26) -> 1300 | K26: =I26-J26 -> 0 | L26: 1 | M26: =IFERROR(I26/L26,"-") -> 1300 | N26: 1300 | Z26: *
B27: =ROW(A27)-4 -> 23 | C27: BeeX | D27: Aプロジェクト | E27: =B27&"_"&C27&"_"&D27 -> 23_BeeX_Aプロジェクト | F27: 人材育成 | G27: 失注 | H27: 啓亮 | I27: 4500 | J27: =SUM(N27:Y27) -> 4500 | K27: =I27-J27 -> 0 | L27: 3 | M27: =IFERROR(I27/L27,"-") -> 1500 | O27: 1500 | P27: 1500 | Q27: 1500 | Z27: *
B28: =ROW(A28)-4 -> 24 | C28: ひらまつ | D28: 育成体系設計 | E28: =B28&"_"&C28&"_"&D28 -> 24_ひらまつ_育成体系設計 | F28: 人材育成 | G28: A | H28: 啓亮 | I28: 3600 | J28: =SUM(N28:Y28) -> 3600 | K28: =I28-J28 -> 0 | L28: 3 | M28: =IFERROR(I28/L28,"-") -> 1200 | R28: 1200 | S28: 1200 | T28: 1200 | Z28: *
B29: =ROW(A29)-4 -> 25 | C29: パラマウントベッド | D29: 女性社員交流会 企画支援 | E29: =B29&"_"&C29&"_"&D29 -> 25_パラマウントベッド_女性社員交流会 企画支援 | F29: その他 | G29: 成立 | H29: 丸田 | I29: 500 | J29: =SUM(N29:Y29) -> 500 | K29: =I29-J29 -> 0 | L29: 1 | M29: =IFERROR(I29/L29,"-") -> 500 | N29: 500 | Z29: *
B30: =ROW(A30)-4 -> 26 | C30: 西武HD | D30: オンボーディング・OJT企画 | E30: =B30&"_"&C30&"_"&D30 -> 26_西武HD_オンボーディング・OJT企画 | F30: その他 | G30: 失注 | H30: 小川 | I30: 2000 | J30: =SUM(N30:Y30) -> 2000 | K30: =I30-J30 -> 0 | L30: 3 | M30: =IFERROR(I30/L30,"-") -> 666.66667 | O30: 1000 | P30: 1000 | Z30: *
B31: =ROW(A31)-4 -> 27 | C31: PHCホールディングス | D31: オンボ・採用支援（中長期含） | E31: =B31&"_"&C31&"_"&D31 -> 27_PHCホールディングス_オンボ・採用支援（中長期含） | F31: その他 | G31: C | H31: 小川 | I31: 6000 | J31: =SUM(N31:Y31) -> 6000 | K31: =I31-J31 -> 0 | L31: 3 | M31: =IFERROR(I31/L31,"-") -> 2000 | O31: 2000 | P31: 2000 | Q31: 2000 | Z31: *
B32: =ROW(A32)-4 -> 28 | C32: 安田工業 | D32: 人事戦略検討 | E32: =B32&"_"&C32&"_"&D32 -> 28_安田工業_人事戦略検討 | F32: その他 | G32: D | H32: 小川 | I32: 12000 | J32: =SUM(N32:Y32) -> 12000 | K32: =I32-J32 -> 0 | L32: 6 | M32: =IFERROR(I32/L32,"-") -> 2000 | O32: 2000 | P32: 2000 | Q32: 2000 | R32: 2000 | S32: 2000 | T32: 2000 | Z32: *
B33: =ROW(A33)-4 -> 29 | C33: パラマウントベッド | D33: 女性社員交流会 キックオフイベント支援 | E33: =B33&"_"&C33&"_"&D33 -> 29_パラマウントベッド_女性社員交流会 キックオフイベント支援 | F33: その他 | G33: 成立 | H33: 丸田 | I33: 700 | J33: =SUM(N33:Y33) -> 280 | K33: =I33-J33 -> 420 | L33: 1 | M33: =IFERROR(I33/L33,"-") -> 700 | O33: 280 | Z33: *
B34: =ROW(A34)-4 -> 30 | C34: パラマウントベッド | D34: 女性社員交流会_女性キャリア研修 | E34: =B34&"_"&C34&"_"&D34 -> 30_パラマウントベッド_女性社員交流会_女性キャリア研修 | F34: その他 | G34: 成立 | H34: 丸田 | I34: 1164 | J34: =SUM(N34:Y34) -> 232 | K34: =I34-J34 -> 932 | L34: 2 | M34: =IFERROR(I34/L34,"-") -> 582 | Q34: 232 | Z34: *
B35: 31 | C35: パーソルクロステクノロジー | D35: 社内広報業務支援 | E35: =B35&"_"&C35&"_"&D35 -> 31_パーソルクロステクノロジー_社内広報業務支援 | F35: 組織開発 | G35: 成立 | H35: 丸田 | I35: 2250 | J35: =SUM(N35:Y35) -> 2250 | K35: =I35-J35 -> 0 | L35: 3 | M35: =IFERROR(I35/L35,"-") -> 750 | O35: 750 | P35: 750 | Q35: 750 | Z35: *
B36: 32 | C36: ソフトバンク | D36: スキルマップ作成 | E36: =B36&"_"&C36&"_"&D36 -> 32_ソフトバンク_スキルマップ作成 | F36: 人材育成 | G36: 失注 | H36: 啓亮 | I36: 4500 | J36: =SUM(N36:Y36) -> 4500 | K36: =I36-J36 -> 0 | L36: 3 | M36: =IFERROR(I36/L36,"-") -> 1500 | R36: 1500 | S36: 1500 | T36: 1500 | Z36: *
B37: 33 | C37: 田島ルーフィング | D37: 推せる職場診断 | E37: =B37&"_"&C37&"_"&D37 -> 33_田島ルーフィング_推せる職場診断 | F37: 組織開発 | G37: 成立 | H37: 啓亮 | I37: 3100 | J37: 3100 | K37: =I37-J37 -> 0 | L37: 5 | M37: =IFERROR(I37/L37,"-") -> 620 | O37: 1000 | P37: 1000 | Q37: 300 | R37: 300 | S37: 500 | Z37: *
B38: 34 | C38: インテージテクノスフィア | D38: 経営層向けレポート作成支援_Phase1 | E38: =B38&"_"&C38&"_"&D38 -> 34_インテージテクノスフィア_経営層向けレポート作成支援_Phase1 | F38: その他 | G38: 失注 | H38: 弓本 | I38: 900 | J38: =SUM(N38:Y38) -> 900 | K38: =I38-J38 -> 0 | L38: 1 | M38: =IFERROR(I38/L38,"-") -> 900 | O38: 900 | Z38: *
B39: 35 | C39: ソフトバンク | D39: スキルマップ作成 | E39: =B39&"_"&C39&"_"&D39 -> 35_ソフトバンク_スキルマップ作成 | F39: 人材育成 | G39: 失注 | H39: 啓亮 | I39: 15000 | J39: =SUM(N39:Y39) -> 15000 | K39: =I39-J39 -> 0 | L39: 5 | M39: =IFERROR(I39/L39,"-") -> 3000 | O39: 1000 | P39: 2500 | Q39: 2500 | R39: 3000 | S39: 3000 | T39: 3000 | Z39: *
